Workbook

Sheet Analisa 3
A1: ANALISA BIAYA SURVEY MEKANIKA TANAH
A4: NO | B4: URAIAN | C4: SAT. | D4: VOL. | E4: HARGA SAT. | F4: JUMLAH | G4: KETERANGAN
B5: Pengeboran Mesin
B6: Pengeboran mesin | C6: m | D6: 1 | E6: 500000 | F6: =+E6*D6 -> 500000
E7: Jumlah | F7: =SUM(F6:F6) -> 500000
A9: NO | B9: URAIAN | C9: SAT. | D9: VOL. | E9: HARGA SAT. | F9: JUMLAH | G9: KETERANGAN
B10: Pengujian Standard Penetrasi
B11: SPT | C11: kali | D11: 1 | E11: 150000 | F11: =+E11*D11 -> 150000
E12: Jumlah | F12: =SUM(F11:F11) -> 150000
A14: NO | B14: URAIAN | C14: SAT. | D14: VOL. | E14: HARGA SAT. | F14: JUMLAH | G14: KETERANGAN
B15: Pengambilan Sampel Tanah | J15: Uji sampel di Laboratorium | M15: HARGA PP 38 TAHUN 2012
B16: Pengambilan sampe tanah DS dan UDS | C16: tabung | D16: 1 | E16: 150000 | F16: =+E16*D16 -> 150000 | J16: Kadar air | M16: 15000
E17: Jumlah | F17: =SUM(F16:F16) -> 150000 | J17: Berat Jenis Tanah | M17: 18000
J18: Atterberg Limit | M18: 40000
A19: NO | B19: URAIAN | C19: SAT. | D19: VOL. | E19: HARGA SAT. | F19: JUMLAH | G19: KETERANGAN | J19: Analisa Saringan | M19: 35000
B20: Uji sampel di Laboratorium | J20: Hidrometer | M20: 50000
B21: Kadar air | C21: 1 | D21: sampel | E21: 20000 | F21: =C21*E21 -> 20000 | J21: Shringkage Limit | M21: 25000
B22: Berat Jenis Tanah | C22: 1 | D22: sampel | E22: 20000 | F22: =C22*E22 -> 20000 | J22: Unconfined Compression Test | M22: 60000
B23: Atterberg Limit | C23: 1 | D23: sampel | E23: 40000 | F23: =C23*E23 -> 40000 | J23: Konsolidasi | M23: 90000
B24: Analisa Saringan | C24: 1 | D24: sampel | E24: 35000 | F24: =C24*E24 -> 35000 | J24: Berat Isi | M24: 15000
B25: Hidrometer | C25: 1 | D25: sampel | E25: 50000 | F25: =C25*E25 -> 50000 | J25: Kuat Geser (UU) | M25: 80000
B26: Shringkage Limit | C26: 1 | D26: sampel | E26: 25000 | F26: =C26*E26 -> 25000 | J26: Kuat Geser (CU/CD) | M26: 125000
B27: Unconfined Compression Test | C27: 1 | D27: sampel | E27: 60000 | F27: =C27*E27 -> 60000 | J27: Kuat Geser Residual | M27: 250000
B28: Konsolidasi | C28: 1 | D28: sampel | E28: 90000 | F28: =C28*E28 -> 90000 | J28: Permeabilitas | M28: 75000
B29: Berat Isi | C29: 1 | D29: sampel | E29: 15000 | F29: =C29*E29 -> 15000 | J29: Triaxial UU | M29: 90000
B30: Kuat Geser | C30: 1 | D30: sampel | E30: 100000 | F30: =C30*E30 -> 100000 | J30: Triaxial (CU) | M30: 150000
B31: Permeabilitas | C31: 1 | D31: sampel | E31: 75000 | F31: =C31*E31 -> 75000 | M31: =SUM(M16:M30) -> 1118000
B32: Triaxial | C32: 1 | D32: sampel | E32: 120000 | F32: =C32*E32 -> 120000
E33: Jumlah | F33: =SUM(F21:F32) -> 650000
A35: NO | B35: URAIAN | C35: SAT. | D35: VOL. | E35: HARGA SAT. | F35: JUMLAH | G35: KETERANGAN
B36: Uji Bor Tangan (maksimum kedalaman 5 meter)
B37: Bor Tangan | C37: m | D37: 1 | E37: 500000 | F37: =+E37*D37 -> 500000
E39: Jumlah | F39: =SUM(F37:F37) -> 500000
A41: NO | B41: URAIAN | C41: SAT. | D41: VOL. | E41: HARGA SAT. | F41: JUMLAH | G41: KETERANGAN
B42: Uji Sondir (Dutch Cone Penetration Test)
B43: Uji Sondir | C43: titik | D43: 1 | E43: 3000000 | F43: =+E43*D43 -> 3000000
E45: Jumlah | F45: =SUM(F43:F43) -> 3000000
A47: NO | B47: URAIAN | C47: SAT. | D47: VOL. | E47: HARGA SAT. | F47: JUMLAH | G47: KETERANGAN
B48: Bagan untuk Bor Mesin di Laut
B49: Pembuatan Bagan | C49: titik | D49: 1 | E49: 10000000 | F49: =+E49*D49 -> 10000000
...

Sheet Sheet1
A1: TABEL 3-16
A2: BIAYA LANGSUNG PERSONIL (REMUNERATION/BILLING RATE TAHUN 2016)
A3: UNTUK TENAGA SUB PROFESIONAL
A4: BILLING RATE INKINDO TAHUN 2016
A6: No. | B6: PERSONIL | C6: Rp. /Bln
B7: CAD/CAM Operator
B8: Software programmer/

Sheet Resume
A7: REKAPITULASI MUTUAL CHECK ( MC - 0%)
A9: PROYEK | C9: : | D9: KAMPUNG NELAYAN MERAH PUTIH
A10: LOKASI | C10: : | D10: DESA TAMBAKAGUNG, KEC. KALIORI
D11: KAB. REMBANG - PROVINSI JAWA TENGAH
A12: TAHUN ANGGARAN | C12: : | D12: 2026
A14: NO | B14: JENIS PEKERJAAN | E14: NILAI HPS | F14: NILAI PEKERJAAN | G14: NILAI KONTRAK | H14: NILAI MC - O | I14: KDN
A17: 1 | B17: ='Sub Resume'!B11 -> PEKERJAAN PERSIAPAN | E17: ='Sub Resume'!G11 -> 3.7645963e+08 | F17: ='Sub Resume'!H11 -> 3.7504654e+08 | G17: ='Sub Resume'!I11 -> 3.2203949e+08 | H17: ='Sub Resume'!I11 -> 3.2203949e+08 | I17: =(F17/F$37)*H17 -> 51565221
A19: =A17+1 -> 2 | B19: ='Sub Resume'!B12 -> PEKERJAAN DINDING PENAHAN TANAH | E19: ='Sub Resume'!G12 -> 1.9553833e+08 | F19: ='Sub Resume'!H12 -> 1.9334367e+08 | G19: ='Sub Resume'!I12 -> 1.9334367e+08 | H19: ='Sub Resume'!I12+'Sub Resume'!J12 -> 3.9417533e+08 | I19: =(F19/F$37)*H19 -> 32537336
A21: =A19+1 -> 3 | B21: ='Sub Resume'!B14 -> PEKERJAAN BANGUNAN SHELTER PENDARATAN IKAN | E21: ='Sub Resume'!G14 -> 1.255371e+08 | F21: ='Sub Resume'!H14 -> 1.2416543e+08 | G21: ='Sub Resume'!I14 -> 1.2416543e+08 | H21: ='Sub Resume'!I14 -> 1.2416543e+08 | I21: =(F21/F$37)*H21 -> 6582092.1
A23: =A21+1 -> 4 | B23: ='Sub Resume'!B18 -> PEKERJAAN PONDASI PABRIK ES PORTABLE | E23: ='Sub Resume'!G18 -> 2.0536648e+08 | F23: ='Sub Resume'!H18 -> 2.0240125e+08 | G23: ='Sub Resume'!I18 -> 2.0240125e+08 | H23: ='Sub Resume'!I18 -> 2.0240125e+08 | I23: =(F23/F$37)*H23 -> 17489966
A25: =A23+1 -> 5 | B25: ='Sub Resume'!B21 -> PEKERJAAN BANGUNAN KIOS PERBEKALAN | E25: ='Sub Resume'!G21 -> 1.7647042e+08 | F25: ='Sub Resume'!H21 -> 1.7486835e+08 | G25: ='Sub Resume'!I21 -> 1.7486835e+08 | H25: ='Sub Resume'!I21 -> 1.7486835e+08 | I25: =(F25/F$37)*H25 -> 13055244
A27: =A25+1 -> 6 | B27: ='Sub Resume'!B25 -> PEKERJAAN PLUMBING DISTRIBUSI AIR BERSIH DAN SUMUR BOR | E27: ='Sub Resume'!G25 -> 2.9731463e+08 | F27: ='Sub Resume'!H25 -> 2.9378254e+08 | G27: ='Sub Resume'!I25 -> 2.9378254e+08 | H27: ='Sub Resume'!I25 -> 2.9378254e+08 | I27: =(F27/F$37)*H27 -> 36848053
A29: =A27+1 -> 7 | B29: ='Sub Resume'!B29 -> PEKERJAAN PENERANGAN KAWASAN | E29: ='Sub Resume'!G29 -> 3.2115133e+08 | F29: ='Sub Resume'!H29 -> 3.2819893e+08 | G29: ='Sub Resume'!I29 -> 3.2819893e+08 | H29: ='Sub Resume'!I29 -> 3.2819893e+08 | I29: =(F29/F$37)*H29 -> 45987192
A31: =A29+1 -> 8 | B31: ='Sub Resume'!B32 -> PEKERJAAN JALAN LINGKUNGAN DAN SALURAN | E31: ='Sub Resume'!G32 -> 5.6490156e+08 | F31: ='Sub Resume'!H32 -> 5.6019536e+08 | G31: ='Sub Resume'!I32 -> 5.6019536e+08 | H31: ='Sub Resume'!I32-'Sub Resume'!K32 -> 2.9023103e+08 | I31: =(F31/F$37)*H31 -> 69413817
A33: =A31+1 -> 9 | B33: ='Sub Resume'!B36 -> PEKERJAAN LANDSKAPING KAWASAN | E33: ='Sub Resume'!G36 -> 30720881 | F33: ='Sub Resume'!H36 -> 30533548 | G33: ='Sub Resume'!I36 -> 30533548 | H33: ='Sub Resume'!I36 -> 30533548 | I33: =(F33/F$37)*H33 -> 398031.2
A35: =A33+1 -> 10 | B35: ='Sub Resume'!B37 -> PEKERJAAN LEVELLING LAHAN | E35: ='Sub Resume'!G37 -> 60624208 | F35: ='Sub Resume'!H37 -> 59736881 | G35: ='Sub Resume'!I37 -> 59736881 | H35: ='Sub Resume'!L37 -> 1.2886955e+08 | I35: =(F35/F$37)*H35 -> 3286665
D37: I. JUMLAH | E37: =SUM(E17:E35) -> 2.3540846e+09 | F37: =SUM(F17:F35) -> 2.3422725e+09 | G37: =SUM(G17:G35) -> 2.2892654e+09 | H37: =SUM(H17:H35) -> 2.2892654e+09 | I37: =SUM(I17:I35) -> 2.7716362e+08
D38: II. PPN 11 % | E38: =E37*11% -> 2.589493e+08 | F38: =F37*11% -> 2.5764997e+08 | G38: =G37*11% -> 2.518192e+08 | H38: =H37*0.11 -> 2.518192e+08
D39: III. TOTAL I + II | E39: =E37+E38 -> 2.6130339e+09 | F39: =F37+F38 -> 2.5999225e+09 | G39: =G37+G38 -> 2.5410846e+09 | H39: =H38+H37 -> 2.5410846e+09
D40: IV. DIBULATKAN | E40: =ROUNDDOWN(E39,-3) -> 2613033000 | F40: =ROUNDDOWN(F39,-3) -> 2599922000 | G40: =ROUNDDOWN(G39,-3) -> 2541084000 | H40: =ROUNDDOWN(H39,-3) -> 2541084000
A41: Terbilang : Dua Miliyar Lima Enam Ratus Juta Tujuh Ratus Empat Puluh Enam Ribu Rupiah
F44: 20 Juli 2026
H45: Rembang, 02 Agustus 2026
B46: Diperiksa Oleh : | G46: Di Buat Oleh :
B47: PT AGRINAS JALADRI NUSANTARA | G47: PT KURNIA ALAM SENTOSA
B53: M. Nazar Iqbal | G53: Khusnul Yaqin
B54: Team Leader | G54: Direktur
B56: Di Setujui | G56: Mengetahui
B57: Wakil Syah PPK | G57: PPK Satuan Kerja Sekretariat Direktorat Jenderal Perikanan Tangkap
B62: Elfando Mada | G62: Umar
B63: NIP 199106202015031001 | G63: NIP 198007052005021001

Sheet Sub Resume
A2: SUB RESUME MUTUAL CHECK (MC-0)
A4: =Resume!A9 -> PROYEK | C4: =Resume!C9 -> : | D4: =Resume!D9 -> KAMPUNG NELAYAN MERAH PUTIH
A5: =Resume!A10 -> LOKASI | C5: =Resume!C10 -> : | D5: =Resume!D10 -> DESA TAMBAKAGUNG, KEC. KALIORI
D6: =Resume!D11 -> KAB. REMBANG - PROVINSI JAWA TENGAH
A7: =Resume!A12 -> TAHUN ANGGARAN | C7: =Resume!C12 -> : | D7: =Resume!D12 -> 2026
A9: NO | B9: JENIS PEKERJAAN | G9: NILAI HPS | H9: NILAI PEKERJAAN | I9: NILAI KONTRAK | J9: NILAI PEK. TAMBAH | K9: NILAI PEK. KURANG | L9: MC - 0 | M9: KET
A11: =RAB!A13 -> I | B11: =RAB!B13 -> PEKERJAAN PERSIAPAN | G11: =RAB!H71 -> 3.7645963e+08 | H11: =RAB!J71 -> 3.7504654e+08 | I11: =RAB!M71 -> 3.2203949e+08 | L11: =RAB!Y71 -> 3.2203949e+08 | M11: TETAP
A12: II | B12: =RAB!B72 -> PEKERJAAN DINDING PENAHAN TANAH | G12: =SUM(G13:G13) -> 1.9553833e+08 | H12: =SUM(H13:H13) -> 1.9334367e+08 | I12: =SUM(I13:I13) -> 1.9334367e+08 | J12: =J13 -> 2.0083166e+08 | L12: =L13 -> 3.9417533e+08 | M12: PEK. TAMBAH
A13: II.1 | B13: =RAB!B73 -> Pekerjaan Turap Beton | G13: =RAB!H89 -> 1.9553833e+08 | H13: =RAB!J89 -> 1.9334367e+08 | I13: =RAB!M89 -> 1.9334367e+08 | J13: =RAB!Q89 -> 2.0083166e+08 | L13: =RAB!Y89 -> 3.9417533e+08 | M13: =M12 -> PEK. TAMBAH
A14: III | B14: =RAB!B90 -> PEKERJAAN BANGUNAN SHELTER PENDARATAN IKAN | G14: =SUM(G15:G17) -> 1.255371e+08 | H14: =SUM(H15:H17) -> 1.2416543e+08 | I14: =SUM(I15:I17) -> 1.2416543e+08 | L14: =I14 -> 1.2416543e+08 | M14: =M11 -> TETAP
A15: III.1 | B15: =RAB!B91 -> Pekerjaan Struktural | G15: =RAB!H144 -> 54099474 | H15: =RAB!J144 -> 53121547 | I15: =RAB!M144 -> 53121547 | L15: =I15 -> 53121547 | M15: =M14 -> TETAP
A16: III.2 | B16: =RAB!B145 -> Pekerjaan Arsitektural | G16: =RAB!H169 -> 65149607 | H16: =RAB!J169 -> 64641313 | I16: =RAB!M169 -> 64641313 | L16: =I16 -> 64641313 | M16: =M14 -> TETAP
A17: III.3 | B17: =RAB!B170 -> Pekerjaan Elektrikal | G17: =RAB!H180 -> 6288016.7 | H17: =RAB!J180 -> 6402567.7 | I17: =RAB!M180 -> 6402567.7 | L17: =I17 -> 6402567.7 | M17: =M14 -> TETAP
A18: IV | B18: =RAB!B232 -> PEKERJAAN PONDASI PABRIK ES PORTABLE | G18: =G19+G20 -> 2.0536648e+08 | H18: =H19+H20 -> 2.0240125e+08 | I18: =I19+I20 -> 2.0240125e+08 | L18: =I18 -> 2.0240125e+08 | M18: =M14 -> TETAP
A19: IV.1 | B19: =RAB!B233 -> Pekerjaan Struktural Pondasi | G19: =RAB!H271 -> 1.5556949e+08 | H19: =RAB!J271 -> 1.525586e+08 | I19: =RAB!M271 -> 1.525586e+08 | L19: =I19 -> 1.525586e+08 | M19: =M14 -> TETAP
A20: IV.2 | B20: =RAB!B272 -> Pekerjaan Struktural Ground Water Tank Beton | G20: =RAB!H309 -> 49796991 | H20: =RAB!J309 -> 49842652 | I20: =RAB!M309 -> 49842652 | L20: =I20 -> 49842652 | M20: =M14 -> TETAP
A21: V | B21: =RAB!B418 -> PEKERJAAN BANGUNAN KIOS PERBEKALAN | G21: =SUM(G22:G24) -> 1.7647042e+08 | H21: =SUM(H22:H24) -> 1.7486835e+08 | I21: =SUM(I22:I24) -> 1.7486835e+08 | L21: =I21 -> 1.7486835e+08 | M21: =M19 -> TETAP
A22: V.1 | B22: =RAB!B419 -> Pekerjaan Struktural | G22: =RAB!H488 -> 49209099 | H22: =RAB!J488 -> 48283231 | I22: =RAB!M488 -> 48283231 | L22: =I22 -> 48283231 | M22: =M19 -> TETAP
A23: V.2 | B23: =RAB!B489 -> Pekerjaan Arsitektural | G23: =RAB!H530 -> 89559169 | H23: =RAB!J530 -> 88418196 | I23: =RAB!M530 -> 88418196 | L23: =I23 -> 88418196 | M23: =M19 -> TETAP
A24: V.3 | B24: =RAB!B531 -> Pekerjaan Mekanikal Elektrikal | G24: =RAB!H572 -> 37702151 | H24: =RAB!J572 -> 38166919 | I24: =RAB!M572 -> 38166919 | L24: =I24 -> 38166919 | M24: =M19 -> TETAP
A25: VI | B25: =RAB!B960 -> PEKERJAAN PLUMBING DISTRIBUSI AIR BERSIH DAN SUMUR BOR | G25: =SUM(G26:G28) -> 2.9731463e+08 | H25: =SUM(H26:H28) -> 2.9378254e+08 | I25: =SUM(I26:I28) -> 2.9378254e+08 | L25: =I25 -> 2.9378254e+08 | M25: =M19 -> TETAP
A26: VI.1 | B26: =RAB!B1017 -> Pekerjaan Plumbing Distribusi Air Bersih | G26: =RAB!H1039 -> 23838759 | H26: =RAB!J1039 -> 23979572 | I26: =RAB!M1039 -> 23979572 | L26: =I26 -> 23979572 | M26: =M19 -> TETAP
A27: VI.2 | B27: =RAB!B1041 -> Pekerjaan Pengeboran | G27: =RAB!H1061 -> 1.854717e+08 | H27: =RAB!J1061 -> 1.8134875e+08 | I27: =RAB!M1061 -> 1.8134875e+08 | L27: =I27 -> 1.8134875e+08 | M27: =M19 -> TETAP
A28: VI.3 | B28: =RAB!B1062 -> Pekerjaan Pengadaan Dan Material | G28: =RAB!H1069 -> 88004176 | H28: =RAB!J1069 -> 88454221 | I28: =RAB!M1069 -> 88454221 | L28: =I28 -> 88454221 | M28: =M19 -> TETAP
A29: VII | B29: =RAB!B1070 -> PEKERJAAN PENERANGAN KAWASAN | G29: =SUM(G30:G31) -> 3.2115133e+08 | H29: =SUM(H30:H31) -> 3.2819893e+08 | I29: =SUM(I30:I31) -> 3.2819893e+08 | L29: =I29 -> 3.2819893e+08 | M29: =M19 -> TETAP
A30: VII.1 | B30: =RAB!B1071 -> Pekerjaan Penerangan Tiang T = 7 m Dan T = 4 m | G30: =RAB!H1088 -> 76773322 | H30: =RAB!J1088 -> 76970501 | I30: =RAB!M1088 -> 76970501 | L30: =I30 -> 76970501 | M30: =M19 -> TETAP
A31: VII.2 | B31: =RAB!B1089 -> Pekerjaan Elektrikal | G31: =RAB!H1100 -> 2.44378e+08 | H31: =RAB!J1100 -> 2.5122842e+08 | I31: =RAB!M1100 -> 2.5122842e+08 | L31: =I31 -> 2.5122842e+08 | M31: =M19 -> TETAP
A32: VIII | B32: =RAB!B1280 -> PEKERJAAN JALAN LINGKUNGAN DAN SALURAN | G32: =SUM(G33:G35) -> 5.6490156e+08 | H32: =SUM(H33:H35) -> 5.6019536e+08 | I32: =SUM(I33:I35) -> 5.6019536e+08 | K32: =SUM(K33:K35) -> 2.6996433e+08 | L32: =SUM(L33:L35) -> 2.9023103e+08 | M32: PEK. KURANG
A33: VIII.1 | B33: =RAB!B1281 -> Pekerjaan Saluran Batu Belah Kawasan | G33: =RAB!H1308 -> 2.5562251e+08 | H33: =RAB!J1308 -> 2.5158693e+08 | I33: =RAB!M1308 -> 2.5158693e+08 | K33: =RAB!U1308 -> 63786141 | L33: =I33-K33 -> 1.8780079e+08 | M33: =M32 -> PEK. KURANG
A34: VIII.2 | B34: =RAB!B1309 -> Pekerjaan Jalan Beton Kawasan | G34: =RAB!H1328 -> 2.6297706e+08 | H34: =RAB!J1328 -> 2.617573e+08 | I34: =RAB!M1328 -> 2.617573e+08 | K34: =RAB!U1328 -> 2.0617819e+08 | L34: =I34-K34 -> 55579112 | M34: =M32 -> PEK. KURANG
A35: VIII.3 | B35: =RAB!B1329 -> Pekerjaan Pedestrian Kawasan | G35: =RAB!H1337 -> 46301995 | H35: =RAB!J1337 -> 46851122 | I35: =RAB!M1337 -> 46851122 | L35: =I35-K35 -> 46851122 | M35: =M30 -> TETAP
A36: IX | B36: =RAB!B1338 -> PEKERJAAN LANDSKAPING KAWASAN | G36: =RAB!H1344 -> 30720881 | H36: =RAB!J1344 -> 30533548 | I36: =RAB!M1344 -> 30533548 | L36: =I36 -> 30533548 | M36: =M35 -> TETAP
A37: X | B37: =RAB!B1345 -> PEKERJAAN LEVELLING LAHAN | G37: =RAB!H1348 -> 60624208 | H37: =RAB!J1348 -> 59736881 | I37: =RAB!M1348 -> 59736881 | J37: =RAB!Q1348 -> 69132668 | L37: =I37+J37 -> 1.2886955e+08 | M37: PEK. TAMBAH
D38: I. JUMLAH | G38: =Resume!E37 -> 2.3540846e+09 | H38: =Resume!F37 -> 2.3422725e+09 | I38: =I37+I36+I32+I29+I25+I21+I18+I14+I12+I11 -> 2.2892654e+09 | J38: =J37+J12 -> 2.6996433e+08 | K38: =K32 -> 2.6996433e+08 | L38: =L37+L36+L32+L29+L25+L21+L18+L14+L12+L11 -> 2.2892654e+09
D39: II. PPN 11 % | G39: =G38*11% -> 2.589493e+08 | H39: =H38*11% -> 2.5764997e+08 | I39: =I38*11% -> 2.518192e+08 | L39: =L38*0.11 -> 2.518192e+08
D40: III. TOTAL I + II | G40: =G38+G39 -> 2.6130339e+09 | H40: =H38+H39 -> 2.5999225e+09 | I40: =I38+I39 -> 2.5410846e+09 | L40: =L39+L38 -> 2.5410846e+09
D41: IV. DIBULATKAN | G41: =ROUNDDOWN(G40,-3) -> 2613033000 | H41: =ROUNDDOWN(H40,-3) -> 2599922000 | I41: =ROUNDDOWN(I40,-3) -> 2541084000 | L41: =ROUNDDOWN(L40,-3) -> 2541084000
M43: Rembang, 02 Agustus 2026
C44: Diperiksa Oleh : | I44: Di Buat Oleh : | L44: Di Setujui
C45: PT AGRINAS JALADRI NUSANTARA | I45: PT KURNIA ALAM SENTOSA | L45: Wakil Syah PPK
...

Sheet 1 Vol Tangga Pndrtn 15-15
A4: PERHITUNGAN TALUD DINDING PENAHAN TANAH
A6: NO | B6: JENIS PEKERJAAN | C6: PANJANG | D6: LEBAR | E6: TINGGI | F6: JUMLAH | G6: UNIT | H6: VOLUME | I6: SAT | J6: PEMBULATAN | K6: =#VALUE! -> #VALUE!
A9: I | B9: Pekerjaan Tangga Pendaratan (4X50) m²
A10: 1 | B10: Pekerjaan Perancah untuk Jalan Kerja Tangga Pendaratan | C10: 15 | D10: 3 | H10: =ROUNDUP((C10*D10),0.5) -> 45
B11: Lantai beton | C11: =D10 -> 3 | D11: 3 | G11: 2 | H11: =ROUNDUP((C11*D11*G11),0.5) -> 18
B12: Bordes | C12: =D10 -> 3 | D12: =3+(0.85*2) -> 4.7 | G12: 1 | H12: =ROUNDUP((C12*D12*G12),0.5) -> 15
B13: Bordes | C13: 6 | D13: 3 | G13: 0 | H13: =ROUNDUP((C13*D13*G13),0.5) -> 0
H14: =ROUNDUP((SUM(H10:H13)),5) -> 78 | I14: m² | J14: =ROUND((H14),2) -> 78
A15: =A10+1 -> 2 | B15: Pekerjaan Tapak dan Kolom Precast | J15: =ROUND((H15),2) -> 0
A16: 2.1. | B16: Pekerjaan Pondasi Tapak Precast 15x60x60 cm | J16: =ROUND((H16),2) -> 0 | L16: AS Vert | M16: AS Hz
A17: a | B17: Pekerjaan Bekesting Pondasi | C17: 0.6 | D17: 0.15 | F17: 4 | G17: =N17 -> 18 | H17: =ROUNDUP((C17*D17*F17*G17),5)+H18 -> 12.96 | I17: m² | J17: =ROUND((H17),2) -> 12.96 | L17: 9 | M17: 2 | N17: =L17*M17 -> 18
B18: SISI BAWAH | C18: 0.6 | D18: 0.6 | F18: 1 | G18: =G17 -> 18 | H18: =ROUNDUP((C18*D18*F18*G18),5) -> 6.48
A19: b | B19: Pembesian Besi Beton D13 mm | C19: =((0.52+0.07)*2)+0.05 -> 1.23 | D19: 1.04 | E19: 4 | F19: 2 | G19: =G17 -> 18 | H19: =C19*D19*E19*F19*G19 -> 184.2048 | I19: kg | J19: =ROUND((H19),2) -> 184.2
A20: c | B20: Cor Site Mix 1 : 2 : 3 | C20: 0.6 | D20: 0.6 | E20: 0.15 | G20: =G19 -> 18 | H20: =ROUNDUP((C20*D20*E20*G20),5) -> 0.972 | I20: m³ | J20: =ROUND((H20),2) -> 0.97
A21: 2.2. | B21: Pekerjaan Kolom Precast 15/15 cm (28 bh) | J21: =ROUND((H21),2) -> 0
A22: a | B22: Pekerjaan Bekesting Kolom | F22: sisi | J22: =ROUND((H22),2) -> 0 | K22: kolom A | L22: kolom B | M22: kolom C
B23: 27 | D23: 0.15 | E23: 2.75 | F23: 4 | G23: 2 | H23: =D23*E23*F23*G23 -> 3.3 | K23: 4.161 | L23: 4.161 | M23: 4.161 | R23: 5
B24: 28 | D24: =D23 -> 0.15 | E24: 2.75 | F24: =F23 -> 4 | G24: =G23 -> 2 | H24: =D24*E24*F24*G24 -> 3.3 | K24: 4.071 | L24: 4.071 | M24: 4.071
B25: 29 | D25: =D24 -> 0.15 | E25: 2.75 | F25: =F24 -> 4 | G25: =G24 -> 2 | H25: =D25*E25*F25*G25 -> 3.3 | K25: 3.98 | L25: 3.98 | M25: 3.98
A26: bordes | B26: 31 | D26: =D25 -> 0.15 | E26: 1.35 | F26: =F25 -> 4 | G26: =G25 -> 2 | H26: =D26*E26*F26*G26 -> 1.62 | K26: 3.873 | L26: 3.873 | M26: 3.873
A27: bordes | B27: =B26+1 -> 32 | D27: =D26 -> 0.15 | E27: 1.35 | F27: =F26 -> 4 | G27: =G26 -> 2 | H27: =D27*E27*F27*G27 -> 1.62 | K27: 3.755 | L27: 3.755 | M27: 3.755 | R27: 4.75
A28: bordes | B28: 33 | D28: =D27 -> 0.15 | E28: 1.35 | F28: =F27 -> 4 | G28: 2 | H28: =D28*E28*F28*G28 -> 1.62 | K28: 0.872 | L28: 0.872 | M28: 0.872
B29: 35 | D29: =D28 -> 0.15 | E29: =E25 -> 2.75 | F29: =F28 -> 4 | G29: =G28 -> 2 | H29: =D29*E29*F29*G29 -> 3.3 | K29: 0.82 | L29: 0.82 | M29: 0.82
B30: =B29+1 -> 36 | D30: =D29 -> 0.15 | E30: =E29 -> 2.75 | F30: =F29 -> 4 | G30: =G29 -> 2 | H30: =D30*E30*F30*G30 -> 3.3 | K30: 0.75 | L30: 0.75 | M30: 0.75
B31: =B30+1 -> 37 | D31: =D30 -> 0.15 | E31: =E30 -> 2.75 | F31: =F30 -> 4 | G31: =G30 -> 2 | H31: =D31*E31*F31*G31 -> 3.3 | K31: 0.715 | L31: 0.715 | M31: 0.715
B32: 14 | D32: =D31 -> 0.15 | E32: 3.407 | F32: =F31 -> 4 | G32: 0 | H32: =D32*E32*F32*G32 -> 0 | K32: 3.403 | L32: 3.403 | M32: 3.403 | R32: 4.5
B33: =B32+1 -> 15 | D33: =D32 -> 0.15 | E33: 3.407 | F33: =F32 -> 4 | G33: =G32 -> 0 | H33: =D33*E33*F33*G33 -> 0 | K33: 3.396 | L33: 3.396 | M33: 3.396
B34: =B33+1 -> 16 | D34: =D33 -> 0.15 | E34: 3.4 | F34: =F33 -> 4 | G34: =G33 -> 0 | H34: =D34*E34*F34*G34 -> 0 | K34: 3.389 | L34: 3.389 | M34: 3.389
B35: =B34+1 -> 17 | D35: =D34 -> 0.15 | E35: 3.393 | F35: =F34 -> 4 | G35: =G34 -> 0 | H35: =D35*E35*F35*G35 -> 0 | K35: 3.391 | L35: 3.391 | M35: 3.391
B36: =B35+1 -> 18 | D36: =D35 -> 0.15 | E36: 3.386 | F36: =F35 -> 4 | G36: =G35 -> 0 | H36: =D36*E36*F36*G36 -> 0 | K36: 3.402 | L36: 3.402 | M36: 3.402
H37: =ROUNDUP((SUM(H23:H36)),5) -> 24.66 | I37: m² | J37: =ROUND((H37),2) -> 24.66
A38: b | B38: Pembesian Besi Beton D13 mm s/d stek 50 cm ke Lantai
B39: Overlap ke Tapak | C39: 0.2 | H39: =C39 -> 0.2
B40: Overlap ke Lantai | C40: 0.5 | H40: =C40 -> 0.5
D41: Panjang Kolom sisi atas | G41: Total Overlap | H41: =SUM(H39:H40) -> 0.7 | I41: m¹ | J41: =ROUND((H41),2) -> 0.7
B42: =B23 -> 27 | C42: =E23 -> 2.75 | D42: =H$41 -> 0.7 | E42: =13*13*0.006165 -> 1.041885 | F42: 4 | G42: 2 | H42: =(C42+D42)*E42*F42*G42 -> 28.756026
B43: =B24 -> 28 | C43: =E24 -> 2.75 | D43: =H$41 -> 0.7 | E43: =E42 -> 1.041885 | F43: =F42 -> 4 | G43: =G42 -> 2 | H43: =(C43+D43)*E43*F43*G43 -> 28.756026
B44: =B25 -> 29 | C44: =E25 -> 2.75 | D44: =H$41 -> 0.7 | E44: =E43 -> 1.041885 | F44: =F43 -> 4 | G44: =G43 -> 2 | H44: =(C44+D44)*E44*F44*G44 -> 28.756026
B45: =B26 -> 31 | C45: =E26 -> 1.35 | D45: =H$41 -> 0.7 | E45: =E44 -> 1.041885 | F45: =F44 -> 4 | G45: =G44 -> 2 | H45: =(C45+D45)*E45*F45*G45 -> 17.086914
B46: =B27 -> 32 | C46: =E27 -> 1.35 | D46: =H$41 -> 0.7 | E46: =E45 -> 1.041885 | F46: =F45 -> 4 | G46: =G45 -> 2 | H46: =(C46+D46)*E46*F46*G46 -> 17.086914
...

Sheet 1 Vol Tmbtn Prhu 15-15
A4: PERHITUNGAN TALUD DINDING PENAHAN TANAH
A6: NO | B6: JENIS PEKERJAAN | C6: PANJANG | D6: LEBAR | E6: TINGGI | F6: JUMLAH | G6: UNIT | H6: VOLUME | I6: SAT | J6: PEMBULATAN | K6: =#VALUE! -> #VALUE!
A9: I | B9: Pekerjaan Tambatan Perahu (4X50) m²
A10: 1 | B10: Pekerjaan Perancah untuk Pekerjaan Tambatan Perahu (badan kontruksi & 2 sisi Jalan bantu L = 1,2 m) | C10: 54 | D10: 1.5 | H10: =ROUNDUP((C10*D10),0.5) -> 81
C11: =C10 -> 54 | D11: 3 | H11: =ROUNDUP((C11*D11),0.5) -> 162
H12: =ROUNDUP((SUM(H10:H11)),5) -> 243 | I12: m² | J12: =ROUND((H12),2) -> 243
A13: =A10+1 -> 2 | B13: Pekerjaan Bongkaran Perancah | H13: 1 | I13: ls | J13: =ROUND((H13),2) -> 1
A14: =A13+1 -> 3 | B14: Pekerjaan Bongkaran Tambatan Existing | H14: 1 | I14: ls | J14: =ROUND((H14),2) -> 1
A15: =A14+1 -> 4 | B15: Pekerjaan Tapak dan Kolom Precast | J15: =ROUND((H15),2) -> 0
A16: 8.1. | B16: Pekerjaan Pondasi Tapak Precast 15x60x60 cm | J16: =ROUND((H16),2) -> 0 | L16: AS Hz | M16: AS Vert
A17: a | B17: Pekerjaan Bekesting Pondasi | C17: 0.6 | D17: 0.15 | F17: 4 | G17: =N17 -> 108 | H17: =ROUNDUP((C17*D17*F17*G17),5)+H18 -> 77.76 | I17: m² | J17: =ROUND((H17),2) -> 77.76 | L17: =ROUNDUP(C11/1.5,0.1) -> 36 | M17: 3 | N17: =L17*M17 -> 108
B18: SISI BAWAH | C18: 0.6 | D18: 0.6 | F18: 1 | G18: =G17 -> 108 | H18: =ROUNDUP((C18*D18*F18*G18),5) -> 38.88
A19: b | B19: Pembesian Besi Beton D13 mm | C19: =((0.52+0.07)*2)+0.05 -> 1.23 | D19: =13*13*0.006165 -> 1.041885 | E19: 4 | F19: 2 | G19: =G17 -> 108 | H19: =C19*D19*E19*F19*G19 -> 1107.232 | I19: kg | J19: =ROUND((H19),2) -> 1107.23
A20: c | B20: Cor Site Mix 1 : 2 : 3 | C20: 0.6 | D20: 0.6 | E20: 0.15 | G20: =G19 -> 108 | H20: =ROUNDUP((C20*D20*E20*G20),5) -> 5.832 | I20: m³ | J20: =ROUND((H20),2) -> 5.83
A21: 8.2. | B21: Pekerjaan Kolom Precast 15/15 cm
A22: a | B22: Pekerjaan Bekesting Kolom
B23: 1 | D23: 0.15 | E23: 4 | F23: 4 | G23: =G20 -> 108 | H23: =D23*E23*F23*G23 -> 259.2 | R23: 5
B24: 2 | D24: =D23 -> 0.15 | E24: 4.204 | F24: =F23 -> 4 | G24: 0 | H24: =D24*E24*F24*G24 -> 0
B25: 3 | D25: =D24 -> 0.15 | E25: 4.119 | F25: =F24 -> 4 | G25: =G24 -> 0 | H25: =D25*E25*F25*G25 -> 0
B26: =B25+1 -> 4 | D26: =D25 -> 0.15 | E26: 4.028 | F26: =F25 -> 4 | G26: =G25 -> 0 | H26: =D26*E26*F26*G26 -> 0
B27: =B26+1 -> 5 | D27: =D26 -> 0.15 | E27: 3.938 | F27: =F26 -> 4 | G27: =G26 -> 0 | H27: =D27*E27*F27*G27 -> 0 | R27: 4.75
B28: =B27+1 -> 6 | D28: =D27 -> 0.15 | E28: 3.801 | F28: =F27 -> 4 | G28: =G27 -> 0 | H28: =D28*E28*F28*G28 -> 0
B29: =B28+1 -> 7 | D29: =D28 -> 0.15 | E29: 3.716 | F29: =F28 -> 4 | G29: =G28 -> 0 | H29: =D29*E29*F29*G29 -> 0
B30: =B29+1 -> 8 | D30: =D29 -> 0.15 | E30: 3.653 | F30: =F29 -> 4 | G30: =G29 -> 0 | H30: =D30*E30*F30*G30 -> 0
B31: =B30+1 -> 9 | D31: =D30 -> 0.15 | E31: 3.6 | F31: =F30 -> 4 | G31: =G30 -> 0 | H31: =D31*E31*F31*G31 -> 0
B32: =B31+1 -> 10 | D32: =D31 -> 0.15 | E32: 3.548 | F32: =F31 -> 4 | G32: =G31 -> 0 | H32: =D32*E32*F32*G32 -> 0 | R32: 4.5
B33: =B32+1 -> 11 | D33: =D32 -> 0.15 | E33: 3.496 | F33: =F32 -> 4 | G33: =G32 -> 0 | H33: =D33*E33*F33*G33 -> 0
B34: =B33+1 -> 12 | D34: =D33 -> 0.15 | E34: 3.443 | F34: =F33 -> 4 | G34: =G33 -> 0 | H34: =D34*E34*F34*G34 -> 0
B35: =B34+1 -> 13 | D35: =D34 -> 0.15 | E35: 3.402 | F35: =F34 -> 4 | G35: =G34 -> 0 | H35: =D35*E35*F35*G35 -> 0
B36: =B35+1 -> 14 | D36: =D35 -> 0.15 | E36: 3.407 | F36: =F35 -> 4 | G36: =G35 -> 0 | H36: =D36*E36*F36*G36 -> 0
B37: =B36+1 -> 15 | D37: =D36 -> 0.15 | E37: 3.407 | F37: =F36 -> 4 | G37: =G36 -> 0 | H37: =D37*E37*F37*G37 -> 0
B38: =B37+1 -> 16 | D38: =D37 -> 0.15 | E38: 3.4 | F38: =F37 -> 4 | G38: =G37 -> 0 | H38: =D38*E38*F38*G38 -> 0
B39: =B38+1 -> 17 | D39: =D38 -> 0.15 | E39: 3.393 | F39: =F38 -> 4 | G39: =G38 -> 0 | H39: =D39*E39*F39*G39 -> 0
B40: =B39+1 -> 18 | D40: =D39 -> 0.15 | E40: 3.386 | F40: =F39 -> 4 | G40: =G39 -> 0 | H40: =D40*E40*F40*G40 -> 0
B41: =B40+1 -> 19 | D41: =D40 -> 0.15 | E41: 3.396 | F41: =F40 -> 4 | G41: =G40 -> 0 | H41: =D41*E41*F41*G41 -> 0 | R41: 4.25
B42: =B41+1 -> 20 | D42: =D41 -> 0.15 | E42: 3.407 | F42: =F41 -> 4 | G42: =G41 -> 0 | H42: =D42*E42*F42*G42 -> 0
B43: =B42+1 -> 21 | D43: =D42 -> 0.15 | E43: 3.345 | F43: =F42 -> 4 | G43: =G42 -> 0 | H43: =D43*E43*F43*G43 -> 0
B44: =B43+1 -> 22 | D44: =D43 -> 0.15 | E44: 3.263 | F44: =F43 -> 4 | G44: =G43 -> 0 | H44: =D44*E44*F44*G44 -> 0
B45: =B44+1 -> 23 | D45: =D44 -> 0.15 | E45: 3.258 | F45: =F44 -> 4 | G45: =G44 -> 0 | H45: =D45*E45*F45*G45 -> 0
B46: =B45+1 -> 24 | D46: =D45 -> 0.15 | E46: 3.253 | F46: =F45 -> 4 | G46: =G45 -> 0 | H46: =D46*E46*F46*G46 -> 0
...

Sheet RAB
A1: LAMPIRAN MUTUAL CECK (MC-0%)
A3: PROYEK | C3: : | D3: KAMPUNG NELAYAN MERAH PUTIH
A5: LOKASI | C5: : | D5: DESA TAMBAKAGUNG, KEC. KALIORI
D6: KAB. REMBANG - PROVINSI JAWA TENGAH
A7: TAHUN ANGGARAN | C7: : | D7: 2026
M8: =Resume!G37 -> 2.2892654e+09
A9: NO | B9: JENIS PEKERJAAN | E9: VOL | F9: SAT | L9: NILAI KONTRAK | O9: PEKERJAAN TAMBAH | S9: VOLUME KURANG | W9: MC - 0 | AA9: KETERANGAN
L10: HARGA SATUAN | M10: JUMLAH HARGA | N10: BOBOT | O10: VOL | P10: SAT | Q10: JUMLAH HARGA | R10: BOBOT | S10: VOL | T10: SAT | U10: JUMLAH HARGA | V10: BOBOT | W10: VOL | X10: SAT | Y10: JUMLAH HARGA | Z10: BOBOT
G11: HARGA HPS | H11: JUMLAH HPS | I11: HARGA SATUAN | J11: JUMLAH HARGA | K11: TIMPANG | L11: Rp | M11: Rp | N11: PERSEN | Q11: Rp | R11: PERSEN | U11: Rp | V11: PERSEN | Y11: Rp | Z11: PERSEN
A13: I | B13: PEKERJAAN PERSIAPAN
A14: 1 | B14: Buat Bedeng Pekerja Dan Gudang | E14: =5*10 -> 50 | F14: m² | G14: 1405424.9 | H14: =E14*G14 -> 70271248 | I14: ='Resume Analisa'!$D$6 -> 1362404.6 | J14: =E14*I14 -> 68120231 | K14: =IF(H14=0,"",IF(J14<#REF!*H14,"Timpang <"&TEXT(#REF!,"0%"),IF(J14>#REF!*H14,"Timpang >"&TEXT(#REF!,"0%"),"Wajar"))) -> #REF! | L14: 1200000 | M14: =E14*L14 -> 60000000 | N14: =M14/$M$8*100 -> 2.620928 | O14: 0 | Q14: =O14*L14 -> 0 | R14: =Q14/$M$8*100 -> 0 | S14: 0 | U14: =S14*L14 -> 0 | W14: =(E14+O14)-S14 -> 50 | X14: m² | Y14: =W14*L14 -> 60000000 | Z14: =Y14/$M$8*100 -> 2.620928 | AA14: Tetap
A15: =A14+1 -> 2 | B15: Pekerjaan Sewa Rumah untuk Direksi Keetz | E15: 6 | F15: bln | G15: 2500000 | H15: =E15*G15 -> 15000000 | I15: 2579734.6 | J15: =E15*I15 -> 15478408 | K15: =IF(H15=0,"",IF(J15<#REF!*H15,"Timpang <"&TEXT(#REF!,"0%"),IF(J15>#REF!*H15,"Timpang >"&TEXT(#REF!,"0%"),"Wajar"))) -> #REF! | L15: 2200000 | M15: =E15*L15 -> 13200000 | N15: =M15/$M$8*100 -> 0.57660417 | O15: 0 | Q15: =O15*L15 -> 0 | R15: =Q15/$M$8*100 -> 0 | S15: 0 | U15: =S15*L15 -> 0 | W15: =(E15+O15)-S15 -> 6 | X15: bln | Y15: =W15*L15 -> 13200000 | Z15: =Y15/$M$8*100 -> 0.57660417 | AA15: Tetap
A16: =A15+1 -> 3 | B16: Papan Nama Proyek | E16: 1 | F16: bh | G16: 1583875.7 | H16: =E16*G16 -> 1583875.7 | I16: ='Resume Analisa'!$D$7 -> 1545681.2 | J16: =E16*I16 -> 1545681.2 | K16: =IF(H16=0,"",IF(J16<#REF!*H16,"Timpang <"&TEXT(#REF!,"0%"),IF(J16>#REF!*H16,"Timpang >"&TEXT(#REF!,"0%"),"Wajar"))) -> #REF! | L16: 1545681.2 | M16: =E16*L16 -> 1545681.2 | N16: =M16/$M$8*100 -> 0.067518654 | O16: 0 | Q16: =O16*L16 -> 0 | R16: =Q16/$M$8*100 -> 0 | S16: 0 | U16: =S16*L16 -> 0 | W16: =(E16+O16)-S16 -> 1 | X16: bh | Y16: =W16*L16 -> 1545681.2 | Z16: =Y16/$M$8*100 -> 0.067518654 | AA16: Tetap
A17: =A16+1 -> 4 | B17: Listrik Kerja | E17: 6 | F17: bln | G17: 1000000 | H17: =E17*G17 -> 6000000 | I17: 1014075.1 | J17: =E17*I17 -> 6084450.7 | K17: =IF(H17=0,"",IF(J17<#REF!*H17,"Timpang <"&TEXT(#REF!,"0%"),IF(J17>#REF!*H17,"Timpang >"&TEXT(#REF!,"0%"),"Wajar"))) -> #REF! | L17: 1014075.1 | M17: =E17*L17 -> 6084450.7 | N17: =M17/$M$8*100 -> 0.26578179 | O17: 0 | Q17: =O17*L17 -> 0 | R17: =Q17/$M$8*100 -> 0 | S17: 0 | U17: =S17*L17 -> 0 | W17: =(E17+O17)-S17 -> 6 | X17: bln | Y17: =W17*L17 -> 6084450.7 | Z17: =Y17/$M$8*100 -> 0.26578179 | AA17: Tetap
A18: =A17+1 -> 5 | B18: Pekerjaan Pagar Sementara | E18: 100 | F18: m¹ | G18: 471471.94 | H18: =E18*G18 -> 47147194 | I18: ='Resume Analisa'!$D$8 -> 471000.4 | J18: =E18*I18 -> 47100040 | K18: =IF(H18=0,"",IF(J18<#REF!*H18,"Timpang <"&TEXT(#REF!,"0%"),IF(J18>#REF!*H18,"Timpang >"&TEXT(#REF!,"0%"),"Wajar"))) -> #REF! | L18: 350000 | M18: =E18*L18 -> 35000000 | N18: =M18/$M$8*100 -> 1.5288747 | O18: 0 | Q18: =O18*L18 -> 0 | R18: =Q18/$M$8*100 -> 0 | S18: 0 | U18: =S18*L18 -> 0 | W18: =(E18+O18)-S18 -> 100 | X18: m¹ | Y18: =W18*L18 -> 35000000 | Z18: =Y18/$M$8*100 -> 1.5288747 | AA18: Tetap
A19: =A18+1 -> 6 | B19: Pekerjaan Pengadaan SMK3K | Q19: =O19*L19 -> 0 | R19: =Q19/$M$8*100 -> 0 | S19: 0 | U19: =S19*L19 -> 0
A20: 6.1. | B20: Penyiapan RK3K, terdiri atas : | Q20: =O20*L20 -> 0 | R20: =Q20/$M$8*100 -> 0 | S20: 0 | U20: =S20*L20 -> 0
A21: a | B21: Pembuatan Manual, Prosedur, Instruksi Kerja, Ijin Kerja dan Formulir | E21: 2 | F21: set | G21: 1000000 | H21: =E21*G21 -> 2000000 | I21: 1046418.1 | J21: =E21*I21 -> 2092836.1 | K21: =IF(H21=0,"",IF(J21<#REF!*H21,"Timpang <"&TEXT(#REF!,"0%"),IF(J21>#REF!*H21,"Timpang >"&TEXT(#REF!,"0%"),"Wajar"))) -> #REF! | L21: 1046418.1 | M21: =E21*L21 -> 2092836.1 | N21: =M21/$M$8*100 -> 0.091419547 | O21: 0 | Q21: =O21*L21 -> 0 | R21: =Q21/$M$8*100 -> 0 | S21: 0 | U21: =S21*L21 -> 0 | W21: =(E21+O21)-S21 -> 2 | X21: set | Y21: =W21*L21 -> 2092836.1 | Z21: =Y21/$M$8*100 -> 0.091419547 | AA21: Tetap
A22: b | B22: Pembuatan Kartu Identitas Pekerja (KIP) | E22: 50 | F22: org | G22: 7000 | H22: =E22*G22 -> 350000 | I22: 7104.36 | J22: =E22*I22 -> 355218 | K22: =IF(H22=0,"",IF(J22<#REF!*H22,"Timpang <"&TEXT(#REF!,"0%"),IF(J22>#REF!*H22,"Timpang >"&TEXT(#REF!,"0%"),"Wajar"))) -> #REF! | L22: 7104.36 | M22: =E22*L22 -> 355218 | N22: =M22/$M$8*100 -> 0.01551668 | O22: 0 | Q22: =O22*L22 -> 0 | R22: =Q22/$M$8*100 -> 0 | S22: 0 | U22: =S22*L22 -> 0 | W22: =(E22+O22)-S22 -> 50 | X22: org | Y22: =W22*L22 -> 355218 | Z22: =Y22/$M$8*100 -> 0.01551668 | AA22: Tetap
A23: 6.2. | B23: Sosialisasi dan Promosi K3, terdiri atas : | N23: =M23/$M$8*100 -> 0 | Q23: =O23*L23 -> 0 | R23: =Q23/$M$8*100 -> 0 | S23: 0 | U23: =S23*L23 -> 0 | W23: =(E23+O23)-S23 -> 0 | Y23: =W23*L23 -> 0 | Z23: =Y23/$M$8*100 -> 0
A24: a | B24: Induksi K3 (Safety Induction) ; khusus untuk pekerja baru | E24: =E22 -> 50 | F24: org | G24: 7500 | H24: =E24*G24 -> 375000 | I24: 7536.74 | J24: =E24*I24 -> 376837 | K24: =IF(H24=0,"",IF(J24<#REF!*H24,"Timpang <"&TEXT(#REF!,"0%"),IF(J24>#REF!*H24,"Timpang >"&TEXT(#REF!,"0%"),"Wajar"))) -> #REF! | L24: 7536.74 | M24: =E24*L24 -> 376837 | N24: =M24/$M$8*100 -> 0.016461044 | O24: 0 | Q24: =O24*L24 -> 0 | R24: =Q24/$M$8*100 -> 0 | S24: 0 | U24: =S24*L24 -> 0 | W24: =(E24+O24)-S24 -> 50 | X24: org | Y24: =W24*L24 -> 376837 | Z24: =Y24/$M$8*100 -> 0.016461044 | AA24: Tetap
A25: b | B25: Pengarahan K3 (Safety Briefing) : | E25: =E24 -> 50 | F25: org | G25: 7500 | H25: =E25*G25 -> 375000 | I25: 7848.23 | J25: =E25*I25 -> 392411.5 | K25: =IF(H25=0,"",IF(J25<#REF!*H25,"Timpang <"&TEXT(#REF!,"0%"),IF(J25>#REF!*H25,"Timpang >"&TEXT(#REF!,"0%"),"Wajar"))) -> #REF! | L25: 7848.23 | M25: =E25*L25 -> 392411.5 | N25: =M25/$M$8*100 -> 0.017141372 | O25: 0 | Q25: =O25*L25 -> 0 | R25: =Q25/$M$8*100 -> 0 | S25: 0 | U25: =S25*L25 -> 0 | W25: =(E25+O25)-S25 -> 50 | X25: org | Y25: =W25*L25 -> 392411.5 | Z25: =Y25/$M$8*100 -> 0.017141372 | AA25: Tetap
A26: 6.3. | B26: Alat Pelindung Kerja, terdiri atas : | N26: =M26/$M$8*100 -> 0 | Q26: =O26*L26 -> 0 | R26: =Q26/$M$8*100 -> 0 | S26: 0 | U26: =S26*L26 -> 0 | W26: =(E26+O26)-S26 -> 0 | Y26: =W26*L26 -> 0 | Z26: =Y26/$M$8*100 -> 0
A27: a | B27: Pembatas Area (Restricted Area) | E27: 1 | F27: ls | G27: 118500 | H27: =E27*G27 -> 118500 | I27: ='Bahan & Upah'!C141*10*15% -> 124260.49 | J27: =E27*I27 -> 124260.49 | K27: =IF(H27=0,"",IF(J27<#REF!*H27,"Timpang <"&TEXT(#REF!,"0%"),IF(J27>#REF!*H27,"Timpang >"&TEXT(#REF!,"0%"),"Wajar"))) -> #REF! | L27: 124260.49 | M27: =E27*L27 -> 124260.49 | N27: =M27/$M$8*100 -> 0.0054279636 | O27: 0 | Q27: =O27*L27 -> 0 | R27: =Q27/$M$8*100 -> 0 | S27: 0 | U27: =S27*L27 -> 0 | W27: =(E27+O27)-S27 -> 1 | X27: ls | Y27: =W27*L27 -> 124260.49 | Z27: =Y27/$M$8*100 -> 0.0054279636 | AA27: Tetap
A28: 6.4. | B28: Alat Pelindung Diri, terdiri atas : | N28: =M28/$M$8*100 -> 0 | O28: 0 | Q28: =O28*L28 -> 0 | R28: =Q28/$M$8*100 -> 0 | S28: 0 | U28: =S28*L28 -> 0 | W28: =(E28+O28)-S28 -> 0 | Y28: =W28*L28 -> 0 | Z28: =Y28/$M$8*100 -> 0
A29: a | B29: Topi Pelindung (Safety Helmet) | E29: =E22 -> 50 | F29: bh | G29: 75000 | H29: =E29*G29 -> 3750000 | I29: 79112.25 | J29: =E29*I29 -> 3955612.5 | K29: =IF(H29=0,"",IF(J29<#REF!*H29,"Timpang <"&TEXT(#REF!,"0%"),IF(J29>#REF!*H29,"Timpang >"&TEXT(#REF!,"0%"),"Wajar"))) -> #REF! | L29: 79112.25 | M29: =E29*L29 -> 3955612.5 | N29: =M29/$M$8*100 -> 0.1727896 | O29: 0 | Q29: =O29*L29 -> 0 | R29: =Q29/$M$8*100 -> 0 | S29: 0 | U29: =S29*L29 -> 0 | W29: =(E29+O29)-S29 -> 50 | X29: bh | Y29: =W29*L29 -> 3955612.5 | Z29: =Y29/$M$8*100 -> 0.1727896 | AA29: Tetap
A30: b | B30: Pelindung Pernapasan dan Mulut (Masker) | E30: =E29 -> 50 | F30: bh | G30: 5000 | H30: =E30*G30 -> 250000 | I30: 5065.19 | J30: =E30*I30 -> 253259.5 | K30: =IF(H30=0,"",IF(J30<#REF!*H30,"Timpang <"&TEXT(#REF!,"0%"),IF(J30>#REF!*H30,"Timpang >"&TEXT(#REF!,"0%"),"Wajar"))) -> #REF! | L30: 5065.19 | M30: =E30*L30 -> 253259.5 | N30: =M30/$M$8*100 -> 0.011062915 | O30: 0 | Q30: =O30*L30 -> 0 | R30: =Q30/$M$8*100 -> 0 | S30: 0 | U30: =S30*L30 -> 0 | W30: =(E30+O30)-S30 -> 50 | X30: bh | Y30: =W30*L30 -> 253259.5 | Z30: =Y30/$M$8*100 -> 0.011062915 | AA30: Tetap
A31: c | B31: Sarung Tangan (Safety Gloves) | E31: =E30 -> 50 | F31: psg | G31: 5000 | H31: =E31*G31 -> 250000 | I31: 5020.38 | J31: =E31*I31 -> 251019 | K31: =IF(H31=0,"",IF(J31<#REF!*H31,"Timpang <"&TEXT(#REF!,"0%"),IF(J31>#REF!*H31,"Timpang >"&TEXT(#REF!,"0%"),"Wajar"))) -> #REF! | L31: 5020.38 | M31: =E31*L31 -> 251019 | N31: =M31/$M$8*100 -> 0.010965046 | O31: 0 | Q31: =O31*L31 -> 0 | R31: =Q31/$M$8*100 -> 0 | S31: 0 | U31: =S31*L31 -> 0 | W31: =(E31+O31)-S31 -> 50 | X31: psg | Y31: =W31*L31 -> 251019 | Z31: =Y31/$M$8*100 -> 0.010965046 | AA31: Tetap
A32: d | B32: Sepatu Keselamatan (Rubber Safety Shoes and Toe Cap) | E32: =E31 -> 50 | F32: psg | G32: 145000 | H32: =E32*G32 -> 7250000 | I32: 141266.14 | J32: =E32*I32 -> 7063307 | K32: =IF(H32=0,"",IF(J32<#REF!*H32,"Timpang <"&TEXT(#REF!,"0%"),IF(J32>#REF!*H32,"Timpang >"&TEXT(#REF!,"0%"),"Wajar"))) -> #REF! | L32: 141266.14 | M32: =E32*L32 -> 7063307 | N32: =M32/$M$8*100 -> 0.30854032 | O32: 0 | Q32: =O32*L32 -> 0 | R32: =Q32/$M$8*100 -> 0 | S32: 0 | U32: =S32*L32 -> 0 | W32: =(E32+O32)-S32 -> 50 | X32: psg | Y32: =W32*L32 -> 7063307 | Z32: =Y32/$M$8*100 -> 0.30854032 | AA32: Tetap
A33: e | B33: Rompi Keselamatan ( Safety vest) | E33: =E32 -> 50 | F33: bh | G33: 25000 | H33: =E33*G33 -> 1250000 | I33: 25391.62 | J33: =E33*I33 -> 1269581 | K33: =IF(H33=0,"",IF(J33<#REF!*H33,"Timpang <"&TEXT(#REF!,"0%"),IF(J33>#REF!*H33,"Timpang >"&TEXT(#REF!,"0%"),"Wajar"))) -> #REF! | L33: 25391.62 | M33: =E33*L33 -> 1269581 | N33: =M33/$M$8*100 -> 0.055458008 | O33: 0 | Q33: =O33*L33 -> 0 | R33: =Q33/$M$8*100 -> 0 | S33: 0 | U33: =S33*L33 -> 0 | W33: =(E33+O33)-S33 -> 50 | X33: bh | Y33: =W33*L33 -> 1269581 | Z33: =Y33/$M$8*100 -> 0.055458008 | AA33: Tetap
A34: 6.5. | B34: Asuransi dan Perijinan, terdiri atas : | N34: =M34/$M$8*100 -> 0 | O34: 0 | Q34: =O34*L34 -> 0 | R34: =Q34/$M$8*100 -> 0 | S34: 0 | U34: =S34*L34 -> 0 | W34: =(E34+O34)-S34 -> 0 | Y34: =W34*L34 -> 0 | Z34: =Y34/$M$8*100 -> 0
A35: a | B35: BPJS Ketenagakerjaan dan Kesehatan Kerja ; (BERDASARKAN KEPMENAKER NOMOR 44 TAHUN 2015 tentang | E35: 1 | F35: ls | G35: 20000000 | H35: =E35*G35 -> 20000000 | I35: 20000000 | J35: =E35*I35 -> 20000000 | K35: =IF(H35=0,"",IF(J35<#REF!*H35,"Timpang <"&TEXT(#REF!,"0%"),IF(J35>#REF!*H35,"Timpang >"&TEXT(#REF!,"0%"),"Wajar"))) -> #REF! | L35: 12000000 | M35: =E35*L35 -> 12000000 | N35: =M35/$M$8*100 -> 0.52418561 | O35: 0 | Q35: =O35*L35 -> 0 | R35: =Q35/$M$8*100 -> 0 | S35: 0 | U35: =S35*L35 -> 0 | W35: =(E35+O35)-S35 -> 1 | X35: ls | Y35: =W35*L35 -> 12000000 | Z35: =Y35/$M$8*100 -> 0.52418561 | AA35: Tetap
B36: Program JK bagi pekerja harian lepas, borongan | N36: =M36/$M$8*100 -> 0 | O36: 0 | Q36: =O36*L36 -> 0 | R36: =Q36/$M$8*100 -> 0 | S36: 0 | U36: =S36*L36 -> 0 | W36: =(E36+O36)-S36 -> 0 | Y36: =W36*L36 -> 0 | Z36: =Y36/$M$8*100 -> 0
A37: 6.6. | B37: Personil K3, terdiri atas : | N37: =M37/$M$8*100 -> 0 | O37: 0 | Q37: =O37*L37 -> 0 | R37: =Q37/$M$8*100 -> 0 | S37: 0 | U37: =S37*L37 -> 0 | W37: =(E37+O37)-S37 -> 0 | Y37: =W37*L37 -> 0 | Z37: =Y37/$M$8*100 -> 0
A38: a | B38: Petugas K3 | E38: =E17 -> 6 | F38: bln | G38: 7000000 | H38: =E38*G38 -> 42000000 | I38: 6965298.2 | J38: =E38*I38 -> 41791789 | K38: =IF(H38=0,"",IF(J38<#REF!*H38,"Timpang <"&TEXT(#REF!,"0%"),IF(J38>#REF!*H38,"Timpang >"&TEXT(#REF!,"0%"),"Wajar"))) -> #REF! | L38: 6965298.2 | M38: =E38*L38 -> 41791789 | N38: =M38/$M$8*100 -> 1.8255545 | O38: 0 | Q38: =O38*L38 -> 0 | R38: =Q38/$M$8*100 -> 0 | S38: 0 | U38: =S38*L38 -> 0 | W38: =(E38+O38)-S38 -> 6 | X38: bln | Y38: =W38*L38 -> 41791789 | Z38: =Y38/$M$8*100 -> 1.8255545 | AA38: Tetap
A39: 6.7. | B39: Fasilitas Sarana Kesehatan, terdiri atas : | N39: =M39/$M$8*100 -> 0 | O39: 0 | Q39: =O39*L39 -> 0 | R39: =Q39/$M$8*100 -> 0 | S39: 0 | U39: =S39*L39 -> 0 | W39: =(E39+O39)-S39 -> 0 | Y39: =W39*L39 -> 0 | Z39: =Y39/$M$8*100 -> 0
B40: Peralatan P3K (Kotak P3K, Tandu, Tabung Oksigen, Obat Luka, Perban, dll) | E40: 1 | F40: ls | G40: 5500000 | H40: =E40*G40 -> 5500000 | I40: 5814936.8 | J40: =E40*I40 -> 5814936.8 | K40: =IF(H40=0,"",IF(J40<#REF!*H40,"Timpang <"&TEXT(#REF!,"0%"),IF(J40>#REF!*H40,"Timpang >"&TEXT(#REF!,"0%"),"Wajar"))) -> #REF! | L40: 5814936.8 | M40: =E40*L40 -> 5814936.8 | N40: =M40/$M$8*100 -> 0.25400885 | O40: 0 | Q40: =O40*L40 -> 0 | R40: =Q40/$M$8*100 -> 0 | S40: 0 | U40: =S40*L40 -> 0 | W40: =(E40+O40)-S40 -> 1 | X40: ls | Y40: =W40*L40 -> 5814936.8 | Z40: =Y40/$M$8*100 -> 0.25400885 | AA40: Tetap
A41: 6.8. | B41: Rambu-rambu ukuran min. 90x90, terdiri atas : | N41: =M41/$M$8*100 -> 0 | O41: 0 | Q41: =O41*L41 -> 0 | R41: =Q41/$M$8*100 -> 0 | S41: 0 | U41: =S41*L41 -> 0 | W41: =(E41+O41)-S41 -> 0 | Y41: =W41*L41 -> 0 | Z41: =Y41/$M$8*100 -> 0
A42: a | B42: Rambu Petunjuk | E42: 5 | F42: bh | G42: 75000 | H42: =E42*G42 -> 375000 | I42: 71738.34 | J42: =E42*I42 -> 358691.7 | K42: =IF(H42=0,"",IF(J42<#REF!*H42,"Timpang <"&TEXT(#REF!,"0%"),IF(J42>#REF!*H42,"Timpang >"&TEXT(#REF!,"0%"),"Wajar"))) -> #REF! | L42: 71738.34 | M42: =E42*L42 -> 358691.7 | N42: =M42/$M$8*100 -> 0.015668419 | O42: 0 | Q42: =O42*L42 -> 0 | R42: =Q42/$M$8*100 -> 0 | S42: 0 | U42: =S42*L42 -> 0 | W42: =(E42+O42)-S42 -> 5 | X42: bh | Y42: =W42*L42 -> 358691.7 | Z42: =Y42/$M$8*100 -> 0.015668419 | AA42: Tetap
A43: b | B43: Rambu Larangan | E43: 2 | F43: bh | G43: 75000 | H43: =E43*G43 -> 150000 | I43: 76185.04 | J43: =E43*I43 -> 152370.08 | K43: =IF(H43=0,"",IF(J43<#REF!*H43,"Timpang <"&TEXT(#REF!,"0%"),IF(J43>#REF!*H43,"Timpang >"&TEXT(#REF!,"0%"),"Wajar"))) -> #REF! | L43: 76185.04 | M43: =E43*L43 -> 152370.08 | N43: =M43/$M$8*100 -> 0.0066558503 | O43: 0 | Q43: =O43*L43 -> 0 | R43: =Q43/$M$8*100 -> 0 | S43: 0 | U43: =S43*L43 -> 0 | W43: =(E43+O43)-S43 -> 2 | X43: bh | Y43: =W43*L43 -> 152370.08 | Z43: =Y43/$M$8*100 -> 0.0066558503 | AA43: Tetap
...

Sheet 12. Vol Levelling
A1: NO | B1: JENIS PEKERJAAN | C1: PANJANG | D1: LEBAR | E1: TINGGI | F1: JUMLAH | G1: TITIK | H1: SISI | I1: TEKUKAN | J1: OVERLAP | L1: BJ | M1: UNIT | N1: VOLUME | O1: SAT | P1: PEMBULATAN
J2: BAWAH | K2: ATAS
A5: 16 | B5: PEKERJAAN LEVELLING
A6: 1 | B6: Pekerjaan Urugan Tanah mendatangkan | C6: 11.09 | D6: 15.68 | E6: 0.96 | N6: =C6*D6*E6 -> 166.93555 | O6: m³ | P6: =ROUND((N6),2) -> 166.94
A8: 2 | B8: Segmen 1 | C8: 3.23 | D8: 15.68 | E8: 7.65 | N8: =C8*D8*E8 -> 387.44496 | O8: m³ | P8: =ROUND((N8),2) -> 387.44
C9: =(26.5+22.5)/2 -> 24.5 | D9: 13.5 | E9: 0.45 | N9: =C9*D9*E9 -> 148.8375
A10: 3 | B10: Segmen 2 | C10: 14.94 | D10: 15.68 | E10: 0.57 | N10: =C10*D10*E10 -> 133.52774 | O10: m³ | P10: =ROUND((N10),2) -> 133.53
C11: 21 | D11: 13.5 | E11: 0.5 | N11: =C11*D11*E11 -> 141.75
A12: 4 | B12: Segmen 3 | C12: 20.54 | D12: 15.68 | E12: 1.26 | N12: =C12*D12*E12 -> 405.80467 | O12: m³ | P12: =ROUND((N12),2) -> 405.8
C13: 26 | D13: 2 | E13: 1.6 | N13: =C13*D13*E13 -> 83.2
A14: 5 | B14: Segmen 4 | C14: 0.68 | D14: 15.68 | E14: 0.021 | N14: =C14*D14*E14 -> 0.2239104 | O14: m³ | P14: =ROUND((N14),2) -> 0.22
C15: 45 | D15: 2 | E15: 1.8 | N15: =C15*D15*E15 -> 162
H16: dibagi tiap 20 cm
E17: =E6 -> 0.96 | H17: =ROUNDDOWN((E17/0.2),0.5) -> 4
N18: =N9+N11+N13+N15 -> 535.7875 | P18: =N18-P20 -> 368.8475
P19: =193.1958+0.001557 -> 193.19736
A20: =A6+1 -> 2 | B20: Pekerjaan Pemadatan Tanah Urug dengan alat berat tiap 20 cm | C20: vol. urugan tanah | N20: =N6 -> 166.93555 | O20: m³ | P20: =ROUND((N20),2) -> 166.94

Sheet Resume Analisa
A1: RESUME PEKERJAAN
A3: NO | B3: JENIS PEKERJAAN | C3: KODE ANALISA | D3: NILAI PEKERJAAN | E3: NILAI TKDN
A6: 1 | B6: =ANALISA!C5 -> Pembuatan 1 m2 kantor sementara/rumah jaga/gudang semen dan peralatan lantai plesteran, dinding setengah tembok (Lihat Peraturan Menteri Pekerjaan Umum dan Perumahan Rakyat Nomor 8 Tahun 2023 Lampiran B U.1.3.c (c)) | C6: =ANALISA!B5 -> 1.1.2.3 | D6: =ANALISA!G31 -> 1362404.6 | E6: =ANALISA!I29 -> 0.96738246
A7: =A6+1 -> 2 | B7: =ANALISA!C33 -> Pekerjaan 1 buah papan nama pekerjaan ukuran 0,8x1,2 menggunakan multiflex 18 mm, frame besi siku dan tiang kayu 8/12 (Lihat Peraturan Menteri Pekerjaan Umum dan Perumahan Rakyat Nomor 8 Tahun 2023 Lampiran B U.1.3.f.1 (a)) | C7: =ANALISA!B33 -> 1.1.2.1 | D7: =ANALISA!G53 -> 1545681.2 | E7: =ANALISA!I51 -> 0.80437169
A8: =A7+1 -> 3 | B8: =ANALISA!C55 -> Pembuatan 1 m’ pagar sementara dari seng gelombang rangka kayu tinggi 2 meter (Lihat Peraturan Menteri Pekerjaan Umum dan Perumahan Rakyat Nomor 8 Tahun 2023 Lampiran B U.1.1.2 (c)) | C8: =ANALISA!B55 -> 1.1.1.2 | D8: =ANALISA!G77 -> 471000.4 | E8: =ANALISA!I75 -> 0.97287436
A9: =A8+1 -> 4 | B9: =ANALISA!C79 -> Pasangan 1 m’ bouwplank (Lihat Peraturan Menteri Pekerjaan Umum dan Perumahan Rakyat Nomor 8 Tahun 2023 Lampiran B U.1.2.1.d (a)) | C9: =ANALISA!B79 -> 1.1.4.2 | D9: =ANALISA!G96 -> 174862.27 | E9: =ANALISA!I94 -> 0.99657859
A10: =A9+1 -> 5 | B10: =ANALISA!C98 -> Pekerjaan 1 m¹ Pengukuran dan Pematokan Pagar/Saluran | C10: =ANALISA!B98 -> T.02.a | D10: =ANALISA!G112 -> 4395.47 | E10: =ANALISA!I110 -> 1
A11: =A10+1 -> 6 | B11: =ANALISA!C114 -> Pekerjaan 1 Ha Pengukuran Ulang Topografi | C11: =ANALISA!B114 -> 1.1.4.1 | D11: =ANALISA!G132 -> 3280507.4 | E11: =ANALISA!I130 -> 0.5198278
A12: =A11+1 -> 7 | B12: =ANALISA!C134 -> Pekerjaan 1 m² Stake Out Posisi Trase Saluran/Infrastruktur | C12: =ANALISA!B134 -> T.04.a.1 | D12: =ANALISA!G149 -> 3324.91 | E12: =ANALISA!I147 -> 1
A13: =A12+1 -> 8 | B13: =ANALISA!C151 -> Pekerjaan 1 m²Pembersihan dari tanaman/tumbuhan | C13: =ANALISA!B151 -> 1.1.3.3 | D13: =ANALISA!G162 -> 6129.6 | E13: =ANALISA!I160 -> 1
A14: =A13+1 -> 9 | B14: =ANALISA!C165 -> Pekerjaan 1 m² Perancah untuk Pekerjaan Tambatan Perahu (badan kontruksi & 2 sisi Jalan bantu L = 1,2 m) | C14: =ANALISA!B165 -> Analisa Sendiri | D14: =ANALISA!G388 -> 217446.92 | E14: =ANALISA!I388 -> 1
A15: =A14+1 -> 10 | B15: =ANALISA!C391 -> Pekerjaan 1 m3 Mengangkut Material dengan Jarak angkut 66 m | C15: =ANALISA!B391 -> Analisa Sendiri | D15: =ANALISA!G412 -> 434188.12 | E15: =ANALISA!I412 -> 1
A16: =A15+1 -> 11 | B16: =ANALISA!C414 -> Pekerjaan 1 m3 Mengangkut Material dengan Jarak angkut 120 m | C16: =ANALISA!B414 -> Analisa Sendiri | D16: =ANALISA!G435 -> 822205.44 | E16: =ANALISA!I435 -> 1
A17: =A16+1 -> 12 | B17: =ANALISA!C437 -> Pekerjaan 1 Tiang Demobilisasi+Setting Kolom Dan Tapak Precast termasuk pasang Penyokong/Pengaku Tiang | C17: =ANALISA!B437 -> Analisa Sendiri | D17: =ANALISA!G479 -> 249717.86 | E17: =ANALISA!I479 -> 1
A18: =A17+1 -> 13 | B18: =ANALISA!C481 -> Pekerjaan 1 m³ Galian Tanah Biasa sedalam 0 s/d 1 m | C18: =ANALISA!B481 -> 1.2.1.1.3 | D18: =ANALISA!G492 -> 49036.76 | E18: =ANALISA!I490 -> 1
A19: =A18+1 -> 14 | B19: =ANALISA!C494 -> Pekerjaan 1 m³ Galian Tanah Biasa sedalam 1 s/d 2 m | C19: =ANALISA!B494 -> 1.2.1.1.4 | D19: =ANALISA!G505 -> 105018.5 | E19: =ANALISA!I503 -> 1
A20: =A19+1 -> 15 | B20: =ANALISA!C507 -> Pekerjaan 1 m³ Galian Tanah Biasa sedalam 2 s/d 3 m | C20: =ANALISA!B507 -> 1.2.1.1.6 | D20: =ANALISA!G518 -> 124233.94 | E20: =ANALISA!I516 -> 1
A21: =A20+1 -> 16 | B21: =ANALISA!C520 -> Pekerjaan 1 m³ Galian Tanah Cadas/Keras sedalam 0 s/d 1 m | C21: =ANALISA!B520 -> 1.2.3.2.1 | D21: =ANALISA!G532 -> 89046.29 | E21: =ANALISA!I530 -> 1
A22: =A21+1 -> 17 | B22: =ANALISA!C534 -> Pekerjaan 1 m³ Galian Tanah Cadas/Keras sedalam 1 s/d 2 m | C22: =ANALISA!B534 -> 1.2.3.2.2 | D22: =ANALISA!G546 -> 102740.72 | E22: =ANALISA!I544 -> 1
A23: =A22+1 -> 18 | B23: =ANALISA!C599 -> Pekerjaan 1 m³ Buang Tanah bekas Galian Tanah | C23: =ANALISA!B599 -> Analisa Sendiri | D23: =ANALISA!G610 -> 24211.9 | E23: =ANALISA!I608 -> 1
A24: =A23+1 -> 19 | B24: =ANALISA!C612 -> Pekerjaan 1 m³ Urukan tanah biasa atau tanah liat berpasir tanpa pemadatan secara manual (Lihat Peraturan Menteri Pekerjaan Umum dan Perumahan Rakyat Nomor 8 Tahun 2023 Lampiran B U.3.5.1.d (a)) | C24: =ANALISA!B612 -> 1.3.1.4 | D24: =ANALISA!G622 -> 189662.29 | E24: =ANALISA!I620 -> 1
A25: =A24+1 -> 20 | B25: =ANALISA!C636 -> Pekerjaan 1 m³ Pemadatan Tanah dihampar serta dipadatkan dengan alat berat | C25: =ANALISA!B636 -> 10.1.(7) | D25: =ANALISA!G710 -> 168172.15 | E25: =ANALISA!I707 -> 1
A26: =A25+1 -> 21 | B26: =ANALISA!C712 -> Pekerjaan 1 m3 Urukan dengan Pasir Uruk untuk volume s.d 200 m3 tanpa pemadatan secara manual (Lihat Peraturan Menteri Pekerjaan Umum dan Perumahan Rakyat Nomor 8 Tahun 2023 Lampiran B U.3.5.1.b (c)) | C26: =ANALISA!B712 -> 1.3.1.2 | D26: =ANALISA!G722 -> 475358.64 | E26: =ANALISA!I720 -> 1
A27: =A26+1 -> 22 | B27: =ANALISA!C724 -> Pekerjaan 1 m³ Urugan Batu Makadam | C27: =ANALISA!B724 -> 1.3.1.6 | D27: =ANALISA!G734 -> 507538.31 | E27: =ANALISA!I732 -> 1
A28: =A27+1 -> 23 | B28: =ANALISA!C736 -> Pekerjaan 1 m³ Urugan Sirtu | C28: =ANALISA!B736 -> 1.3.1.6 | D28: =ANALISA!G746 -> 438737.73 | E28: =ANALISA!I744 -> 1
A29: =A28+1 -> 24 | B29: =ANALISA!C748 -> Pekerjaan 1 m³ Urugan Gravel | C29: =ANALISA!B748 -> 1.3.1.6 | D29: =ANALISA!G758 -> 827250.2 | E29: =ANALISA!I756 -> 1
A30: =A29+1 -> 25 | B30: =ANALISA!C760 -> Pekerjaan 1 m³ Urugan Tanah Kompos/Subur Mendatangkan | C30: =ANALISA!B760 -> 1.3.1.7 | D30: =ANALISA!G770 -> 465663.72 | E30: =ANALISA!I768 -> 1
A31: =A30+1 -> 26 | B31: =ANALISA!C772 -> Pekerjaan 1 m3 Pemadatan dengan Stamper | C31: =ANALISA!B772 -> 1.3.3.1 | D31: =ANALISA!G780 -> 37946.62 | E31: =ANALISA!I778 -> 1
A32: =A31+1 -> 27 | B32: =ANALISA!C782 -> Pekerjaan 1 m² Penanaman Rumput Gajah Mini | C32: =ANALISA!B782 -> Analisa Sendiri | D32: =ANALISA!G792 -> 133614.54 | E32: =ANALISA!I790 -> 1
A33: =A32+1 -> 28 | B33: =ANALISA!C794 -> Pekerjan 1 ttk Pengujian Crosshole Sonic Logging (CSL) pada tiang bor beton termasuk mobilisasi alat dan personil | C33: =ANALISA!B794 -> G.110 | D33: =ANALISA!G816 -> 11093158 | E33: =ANALISA!I814 -> 1
A34: =A33+1 -> 29 | B34: =ANALISA!C818 -> Pekerjaan 1 m³ Pondasi Batu Kosong / Aanstamping | C34: =ANALISA!B818 -> 2.2.2.1.1 | D34: =ANALISA!G834 -> 824806.04 | E34: =ANALISA!I832 -> 1
A35: =A34+1 -> 30 | B35: =ANALISA!C836 -> Pekerjaan 1 m³ Pondasi Batu Belah 1 : 5 | C35: =ANALISA!B836 -> 2.2.2.1.9 | D35: =ANALISA!G852 -> 1193268.8 | E35: =ANALISA!I850 -> 1
A36: =A35+1 -> 31 | B36: =ANALISA!C854 -> Pekerjaan 1 m³ Pondasi Batu Belah 1 : 2 | C36: =ANALISA!B854 -> 2.2.2.1.2 | D36: =ANALISA!G870 -> 1452345.1 | E36: =ANALISA!I868 -> 1
A37: =A36+1 -> 32 | B37: =ANALISA!C872 -> Pekerjaan 1 m¹ Pengadaan dan Pemancangan Cerucuk Dolken Kayu Ø 6 - 8 cm | C37: =ANALISA!B872 -> 2.6.2.1 | D37: =ANALISA!G887 -> 33453.23 | E37: =ANALISA!I885 -> 0.54387447
A38: =A37+1 -> 33 | B38: =ANALISA!C889 -> Pekerjaan 1 m² Bekisting Kayu untuk Pondasi 3 Kali Pakai | C38: =ANALISA!B889 -> 2.2.1.3.1 | D38: =ANALISA!G905 -> 219134.12 | E38: =ANALISA!I903 -> 0.46792679
A39: =A38+1 -> 34 | B39: =ANALISA!C907 -> Pekerjaan 1 m² Bekisting Kayu untuk Sloof 3 Kali Pakai | C39: =ANALISA!B907 -> 2.2.1.3.3 | D39: =ANALISA!G923 -> 232328.86 | E39: =ANALISA!I921 -> 0.95249221
A40: =A39+1 -> 35 | B40: =ANALISA!C925 -> Pekerjaan 1 m² Bekisting Kayu untuk Kolom 3 Kali Pakai | C40: =ANALISA!B925 -> 2.2.1.3.4 | D40: =ANALISA!G943 -> 245946.97 | E40: =ANALISA!I941 -> 0.93457086
A41: =A40+1 -> 36 | B41: =ANALISA!C946 -> Pekerjaan 1 m² Bekisting Kayu untuk Lantai 3 Kali Pakai | C41: =ANALISA!B946 -> 2.2.1.3.6 | D41: =ANALISA!G964 -> 290443.69 | E41: =ANALISA!I962 -> 0.94459477
A42: =A41+1 -> 37 | B42: =ANALISA!C966 -> Pekerjaan 1 m² Bekisting Kayu untuk Balok 3 Kali Pakai | C42: =ANALISA!B966 -> 2.2.1.3.5 | D42: =ANALISA!G984 -> 252902.38 | E42: =ANALISA!I982 -> 0.93637031
A43: =A42+1 -> 38 | B43: =ANALISA!C986 -> Pekerjaan 1 m² Bekesting Dinding Beton | C43: =ANALISA!B986 -> 2.2.1.3.7 | D43: =ANALISA!G1006 -> 477633.36 | E43: =ANALISA!I1004 -> 0.96630868
...

Sheet Vol Dock Kapal
A1: PERHITUNGAN
A3: NO | B3: JENIS PEKERJAAN | C3: PANJANG | D3: LEBAR | E3: TINGGI | F3: JUMLAH | G3: TITIK | H3: SISI | I3: TEKUKAN | J3: OVERLAP | L3: BJ | M3: UNIT | N3: VOLUME | O3: SAT | P3: PEMBULATAN
J4: BAWAH | K4: ATAS
A7: 24 | B7: Pekerjaan Docking Kapal
A8: 24.1 | B8: Pekerjaan Struktural
A9: 1 | B9: Pekerjaan Bouwplank dan Uitzet | C9: luas pinggir + overlap 1 m
C10: =16.1+1 -> 17.1 | H10: 2 | N10: =C10*H10 -> 34.2
D11: =6+1 -> 7 | H11: 2 | N11: =D11*H11 -> 14
N12: =SUM(N10:N11) -> 48.2 | O12: m² | P12: =ROUND((N12),2) -> 48.2
A13: =A9+1 -> 2 | B13: Pekerjaan Tapak Beton 15x60x60 cm
A14: a | B14: Pekerjaan Galian Tanah s/d 1 m | C14: =0.8+0.1+0.1 -> 1 | D14: =0.8+0.1+0.1 -> 1 | E14: =0.8+0.3+0.03+0.07 -> 1.2 | M14: 8 | N14: =C14*D14*E14*M14 -> 9.6 | O14: m³ | P14: =ROUND((N14),2) -> 9.6
A15: b | B15: Pekerjaan Urugan Pasir t = 7 cm | C15: =C14 -> 1 | D15: =D14 -> 1 | E15: 0.07 | M15: =M14 -> 8 | N15: =C15*D15*E15*M15 -> 0.56 | O15: m³ | P15: =ROUND((N15),2) -> 0.56
A16: c | B16: vertikal | C16: =C15 -> 1 | D16: =D15 -> 1 | E16: 0.03 | M16: =M15 -> 8 | N16: =C16*D16*E16*M16 -> 0.24 | O16: m³ | P16: =ROUND((N16),2) -> 0.24
A17: d | B17: Pekerjaan Bekesting Pasangan Batako | C17: =C16 -> 1 | E17: =E14-0.8-E15-E16 -> 0.3 | H17: 4 | M17: =M16 -> 8 | N17: =C17*E17*H17*M17 -> 9.6 | O17: m² | P17: =ROUND((N17),2) -> 9.6
A18: e | B18: Pekerjaan Pembesian Besi Beton D10 - 150 | C18: 0.45 | F18: =10*10*0.006165 -> 0.6165 | G18: =0.15*2 -> 0.3 | H18: 4 | L18: =ROUNDUP((C18/0.15),0.5) -> 3 | M18: =M17 -> 8 | N18: =(C18+G18)*F18*H18*L18*M18 -> 44.388 | O18: kg | P18: =ROUND((N18),2) -> 44.39
A19: f | B19: Pekerjaan Beton Site Mix 1:2:3 setara fc = 20 | C19: =C14-0.2 -> 0.8 | D19: =D14-0.2 -> 0.8 | E19: =E17 -> 0.3 | M19: =M18 -> 8 | N19: =C19*D19*E19*M19 -> 1.536 | O19: m³ | P19: =ROUND((N19),2) -> 1.54
A20: g | B20: Pekerjaan Cerucuk Kayu Dolken Ø 6 - 8 cm | E20: 4 | L20: 5 | M20: =M19 -> 8 | N20: =E20*L20*M20 -> 160 | O20: m¹ | P20: =ROUND((N20),2) -> 160
A21: =A13+1 -> 3 | B21: Pekerjaan Pondasi Batu Belah
A22: a | B22: Pekerjaan Galian Tanah sedalam 1 m
B23: horisontal | C23: =4+4+1.5+2.5 -> 12 | D23: 0.8 | E23: =0.8+0.07 -> 0.87 | M23: 2 | N23: =C23*D23*E23*M23 -> 16.704
B24: vertikal | C24: 6 | D24: =D23 -> 0.8 | E24: =E23 -> 0.87 | M24: 5 | N24: =C24*D24*E24*M24 -> 20.88
N25: =SUM(N23:N24) -> 37.584 | O25: m³ | P25: =ROUND((N25),2) -> 37.58
C26: 13.5 | D26: =D23 -> 0.8 | E26: =E24 -> 0.87 | M26: 1 | N26: =C26*D26*E26 -> 9.396
C27: 8.5 | D27: =D26 -> 0.8 | E27: =E26 -> 0.87 | M27: 1 | N27: =C27*D27*E27 -> 5.916 | P27: =SUM(N26:N27) -> 15.312
A28: b | B28: Pekerjaan Pancang Cerucuk Dolken
B29: =B23 -> horisontal | C29: =C23 -> 12 | M29: =M23 -> 2 | N29: =C29*M29 -> 24
B30: =B24 -> vertikal | C30: =C24 -> 6 | M30: =M24 -> 5 | N30: =C30*M30 -> 30
N31: =SUM(N29:N30) -> 54
B32: Panjang Pondasi / 50 cm | E32: 4 | F32: =N31/0.5 -> 108 | H32: 2 | N32: =E32*H32*F32 -> 864 | O32: m¹ | P32: =ROUND((N32),2) -> 864
A33: c | B33: Pekerjaan Urugan Pasir urug t = 7 cm
B34: =B23 -> horisontal | C34: =C23 -> 12 | D34: =D23 -> 0.8 | E34: 0.07 | M34: =M23 -> 2 | N34: =C34*D34*E34*M34 -> 1.344
B35: =B24 -> vertikal | C35: =C24 -> 6 | D35: =D24 -> 0.8 | E35: =E34 -> 0.07 | M35: =M24 -> 5 | N35: =C35*D35*E35*M35 -> 1.68 | P35: =ROUND((N36),2) -> 3.02
N36: =SUM(N34:N35) -> 3.024 | O36: m³
C37: 13.5 | D37: =D35 -> 0.8 | E37: =E35 -> 0.07 | N37: =C37*D37*E37 -> 0.756
C38: 8.5 | D38: =D37 -> 0.8 | E38: =E37 -> 0.07 | N38: =C38*D38*E38 -> 0.476 | P38: =SUM(N37:N38) -> 1.232
A39: d | B39: Pekerjaan Lantai Kerja t = 3 cm | N39: =C39*D39*E39 -> 0
B40: =B34 -> horisontal | C40: =C34 -> 12 | D40: =D34 -> 0.8 | E40: 0 | M40: =M34 -> 2 | N40: =C40*D40*E40 -> 0
B41: =B35 -> vertikal | C41: =C35 -> 6 | D41: =D35 -> 0.8 | E41: =E40 -> 0 | M41: =M35 -> 5 | N41: =C41*D41*E41 -> 0
N42: =C42*D42*E42 -> 0 | O42: m³ | P42: =ROUND((N42),2) -> 0
A43: d | B43: Pekerjaan Pondasi Batu Belah 1 : 5
...

Sheet 10. Vol Saluran+Jln
A1: NO | B1: JENIS PEKERJAAN | C1: PANJANG | D1: LEBAR | E1: TINGGI | F1: JUMLAH | G1: TITIK | H1: SISI | I1: TEKUKAN | J1: OVERLAP | L1: BJ | M1: UNIT | N1: VOLUME | O1: SAT | P1: PEMBULATAN
J2: BAWAH | K2: ATAS
A5: V | B5: PEKERJAAN SALURAN DAN JALAN LINGKUNGAN | D5: dekkuer
B6: Panjang Saluran Akses Jalan Masuk | N6: =SUM(N7:N8) -> 3.73
B7: sisi kiri | C7: 0 | D7: 0 | N7: =SUM(C7:M7) -> 0
B8: sisi kanan | C8: 3.13 | D8: 0.6 | N8: =SUM(C8:M8) -> 3.73
B9: Jalan Utama | N9: =SUM(N10:N13) -> 34.72
B10: sisi depan & blkg | C10: 2.04 | D10: 3.8 | H10: 2 | N10: =C10*H10 -> 4.08
B11: sisi samping | C11: 15.32 | D11: 3 | H11: =H10 -> 2 | N11: =C11*H11 -> 30.64
B12: belokan 4 sisi | C12: 0 | H12: 4 | M12: 12 | N12: =C12*H12 -> 0
B13: Akses masuk Bangunan Beku | C13: 0 | H13: 1 | N13: =C13*H13 -> 0
B14: Pedestrian sisi Luar dari kiri | N14: =SUM(N15:N27) -> 3.12
C15: 0 | N15: =C15 -> 0
B16: Jalan Samping Parkiran | C16: 1.65 | D16: 3.2 | N16: =C16 -> 1.65
B17: Jalan Samping Kantor | C17: 1.47 | D17: 2 | N17: =C17 -> 1.47
C18: 0 | N18: =C18 -> 0
B19: depan bangunan beku | C19: 0 | N19: =C19 -> 0
B20: depan area parkir | C20: 0 | N20: =C20 -> 0
C21: 0 | N21: =C21 -> 0
B22: sodetan samping Senkul | C22: 0 | N22: =C22 -> 0
B23: sodetan depan Bale Nelayan | C23: 0 | N23: =C23 -> 0
B24: sodetan blkg Toilet | C24: 0 | N24: =C24 -> 0
B25: depan bengkel | C25: 0 | N25: =C25 -> 0
C26: 0 | N26: =C26 -> 0
C27: 0 | N27: =C27 -> 0
A28: V.1. | B28: Pekerjaan Saluran Kawasan
A29: 1 | B29: Pekerjaan Pengukuran Saluran
B30: =B6 -> Panjang Saluran Akses Jalan Masuk | C30: =N6 -> 3.73 | N30: =SUM(C30:M30) -> 3.73
B31: =B9 -> Jalan Utama | C31: =N9 -> 34.72 | N31: =SUM(C31:M31) -> 34.72
B32: =B14 -> Pedestrian sisi Luar dari kiri | C32: =N14 -> 3.12 | N32: =SUM(C32:M32) -> 3.12
J33: sisi belakang | N33: =SUM(N30:N32)*0+100 -> 100 | O33: m¹ | P33: =ROUND((N33),2) -> 100 | R33: cek siteplan
A34: =A29+1 -> 2 | B34: Pekerjaan Galian Tanah Saluran sampai dengan 1 m | C34: =N33 -> 100 | D34: 1 | E34: 0.8 | N34: =C34*D34*E34 -> 80 | O34: m³ | P34: =ROUND((N34),2) -> 80
A35: =A34+1 -> 3 | B35: Pek. Pemadatan Tanah Galian Saluran dengan Stamper | C35: =C34 -> 100 | D35: =D34 -> 1 | E35: 0.8 | N35: =C35*D35*E35 -> 80 | O35: m³ | P35: =ROUND((N35),2) -> 80
A36: =A35+1 -> 4 | B36: Pekerjaan Saluran Batu Belah 50/40
B37: Dinding | C37: =C35 -> 100 | D37: 0.2 | E37: 0.8 | H37: 2 | N37: =C37*D37*E37*H37 -> 32
B38: Alas | C38: =C37 -> 100 | D38: 0.6 | E38: 0.05 | N38: =C38*D38*E38 -> 3
N39: =SUM(N37:N38) -> 35 | O39: m³ | P39: =ROUND((N39),2) -> 35
A40: =A36+1 -> 5 | B40: Pekerjaan Rabat Beton Lantai Saluran Kawasan t = 5 cm | C40: =C38 -> 100 | D40: 0.6 | E40: 0.05 | N40: =C40*D40*E40 -> 3 | O40: m³ | P40: =ROUND((N40),2) -> 3
A41: =A40+1 -> 6 | B41: Pekerjaan Instalasi Drainase Pipa PVC Ø 4 Inch | C41: =(1.595+1.61)/2 -> 1.6025 | F41: =ROUNDUP((C34/3),0.1) -> 34 | J41: 0.05 | N41: =(C41+J41)*F41 -> 56.185 | O41: m¹ | P41: =ROUND((N41),2) -> 56.19
A42: =A41+1 -> 7 | B42: Pekerjaan Plesteran
...

Sheet 4. Vol DPT
A4: PERHITUNGAN TALUD DINDING PENAHAN TANAH
A6: NO | B6: JENIS PEKERJAAN | C6: PANJANG | D6: LEBAR | E6: TINGGI | F6: JUMLAH | G6: SISI | H6: TEKUKAN | I6: BJ | J6: UNIT | K6: VOLUME | L6: SAT | M6: PEMBULATAN
A9: D | B9: PEKERJAAN BANGUNAN REVETMENT
A10: D.1. | B10: Pekerjaan Turap Beton (DPT) | M10: =ROUND((K10),2) -> 0
A11: 1 | B11: Pek. Tapak Beton Menerus 30 x 140 cm | M11: =ROUND((K11),2) -> 0
B12: Samping Pos Jaga | C12: 10 | K12: =SUM(C12:J12) -> 10 | O12: data ukur langsung Lapangan
B13: Belakang Tambatan | C13: 20 | K13: 20 | O13: data ukur langsung Lapangan
B14: Depan Docking | C14: 20 | K14: 20
K15: =SUM(K12:K14) -> 50 | L15: m¹
A16: a | B16: Pekerjaan Galian Tanah sampai dengan 1 m | C16: 50 | D16: =0.2+0.5+0.5+0.2 -> 1.4 | E16: 0.4 | K16: =C16*D16*E16 -> 28 | L16: m³ | M16: =ROUND((K16),2) -> 28
B17: MC 0 | C17: 71 | D17: =D16 -> 1.4 | E17: =E16 -> 0.4 | K17: =C17*D17*E17 -> 39.76 | L17: m³ | M17: =K17-K16 -> 11.76
A18: b | B18: Pekerjaan Cerucuk Kayu Dolken Ø 6 - 8 cm | E18: 4 | F18: =ROUNDDOWN((K15/0.5),0.5)+1 -> 101 | J18: 3 | K18: =E18*F18*J18 -> 1212 | L18: m¹ | M18: =ROUND((K18),2) -> 1212
B19: MC 0 | E19: 4 | F19: =ROUNDDOWN((C17/0.5),0.5)+1 -> 143 | J19: 3 | K19: =E19*F19*J19 -> 1716 | L19: m138 | M19: =K19-K18 -> 504
A20: b | B20: Pekerjaan Kayu Bekesting Pondasi | C20: =C16 -> 50 | E20: =E16 -> 0.4 | F20: 2 | K20: =(C20+F20)*E20 -> 20.8 | L20: m² | M20: =ROUND((K20),2) -> 20.8
A21: c | B21: Pekerjaan Pembesian Besi Beton D 13 mm - 150 | D21: tekukan | E21: Bj | F21: sisi | J21: jumlah
B22: Tulangan melintang | C22: =D16-0.05*2 -> 1.3 | D22: =0.2*2 -> 0.4 | E22: =13*13*0.006165 -> 1.041885 | F22: 2 | J22: =ROUNDUP((C26/0.15),0.1)+1 -> 334 | K22: =(C22+D22)*E22*F22*J22 -> 1183.1646 | N22: tul. Menerus blm termasuk stek 1 m x 11
K23: =ROUNDUP((SUM(K22:K22)),5) -> 1183.1646 | L23: kg | M23: =ROUND((K23),2) -> 1183.16
B24: MC 0 | C24: =D17-0.05*2 -> 1.3 | D24: =0.2*2 -> 0.4 | E24: =13*13*0.006165 -> 1.041885 | F24: 2 | J24: =ROUNDUP((C27/0.15),0.1)+1 -> 474 | K24: =(C24+D24)*E24*F24*J24 -> 1679.1019 | M24: =K24-K23 -> 495.93726
A25: d | B25: Pekerjaan Pembesian Besi Beton D 10 mm - 150 | D25: tekukan | E25: Bj | F25: sisi | J25: jumlah
B26: Tulangan menerus | C26: =C20-0.05*2 -> 49.9 | D26: =0.2*2 -> 0.4 | E26: =10*10*0.006165 -> 0.6165 | F26: 2 | J26: =ROUNDUP((C22/0.15),0.1)+1 -> 10 | K26: =(C26+D26)*E26*F26*J26 -> 620.199 | L26: kg | M26: =ROUND((K26),2) -> 620.2
B27: MC 0 | C27: 70.9 | D27: =0.2*2 -> 0.4 | E27: =10*10*0.006165 -> 0.6165 | F27: 2 | J27: =J26 -> 10 | K27: =(C27+D27)*E27*F27*J27 -> 879.129 | M27: =K27-K26 -> 258.93
A28: e | B28: Pekerjaan Beton Ready Mix K-300 | C28: =C20 -> 50 | D28: =D16 -> 1.4 | E28: 0.3 | K28: =ROUNDUP((C28*D28*E28),5) -> 21 | L28: m³ | M28: =ROUND((K28),2) -> 21
B29: MC 0 | C29: =C17 -> 71 | D29: =D17 -> 1.4 | E29: 0.3 | K29: =ROUNDUP((C29*D29*E29),5) -> 29.82 | M29: =K29-K28 -> 8.82
A30: f | B30: Pekerjaan Cor Beton dengan Pompa Beton | K30: =K28 -> 21 | L30: m³ | M30: =ROUND((K30),2) -> 21
A31: g | B31: Pekerjaan Pemadatan Beton dengan Vibrator | K31: =K30 -> 21 | L31: m³ | M31: =ROUND((K31),2) -> 21
A32: =A11+1 -> 2 | B32: Pekerjaan Dinding Beton t = 20 cm
A33: a | B33: Pekerjaan Bekesting Dinding 3 kali pakai (sisi luar) | C33: =C20 -> 50 | E33: 0.7 | F33: 2 | K33: =ROUNDUP((C33*E33*F33),5) -> 70 | L33: m² | M33: =ROUND((K33),2) -> 70
B34: ddgx2 + tekukan atas + overlap bawah + overlap tapak | D34: tekukan | E34: Bj | F34: jumlah | J34: sisi
