Workbook

Sheet Resume
A1: RENCANA ANGGARAN BIAYA – RESUME
A2: Lokasi: Pesisir · Paket: KNMP Situbondo · CV. Tosan
A3: Kontrak: B.17114/DJPT.6/PI.420/PPK/VI/2026 · RAB revisi aktif #1
A5: No | B5: Uraian Pekerjaan | C5: Jumlah Harga (Rp)
A6: I | B6: PEKERJAAN PERSIAPAN | C6: ='Sub Resume'!C22 -> 460697021
A7: II | B7: PEKERJAAN REVETMENT | C7: ='Sub Resume'!C32 -> 307935896
A8: V | B8: PEKERJAAN BANGUNAN SHELTER PENDARATAN IKAN | C8: ='Sub Resume'!C38 -> 229436307
A9: VI | B9: PEKERJAAN PONDASI GUDANG BEKU PORTABLE | C9: ='Sub Resume'!C42 -> 221281232
A10: VII | B10: PEKERJAAN PONDASI PABRIK ES PORTABLE | C10: ='Sub Resume'!C47 -> 156432356
A11: VIII | B11: PEKERJAAN AREA PARKIR | C11: ='Sub Resume'!C57 -> 263859953
A12: IX | B12: PEKERJAAN BANGUNAN KIOS PERBEKALAN | C12: ='Sub Resume'!C63 -> 138972135
A13: X | B13: PEKERJAAN BANGUNAN KANTOR PENGELOLA | C13: ='Sub Resume'!C68 -> 302274828
A14: XI | B14: PEKERJAAN BANGUNAN TANGKI AIR DAN SUMUR BOR | C14: ='Sub Resume'!C76 -> 454593106
A15: XII | B15: PEKERJAAN PENERANGAN KAWASAN | C15: ='Sub Resume'!C81 -> 312598200
A16: XIII | B16: PEKERJAAN BANGUNAN GENSET | C16: ='Sub Resume'!C86 -> 187049986
A17: XIV | B17: PEKERJAAN JALAN LINGKUNGAN DAN SALURAN | C17: ='Sub Resume'!C92 -> 207900525
A18: XV | B18: PEKERJAAN LANDSKAPING KAWASAN | C18: ='Sub Resume'!C100 -> 10495186
A19: XVI | B19: PEKERJAAN LEVELLING LAHAN | C19: ='Sub Resume'!C105 -> 115569525
A20: XVII | B20: PEKERJAAN BANGUNAN DOCKING KAPAL | C20: ='Sub Resume'!C111 -> 318286865
A21: XVIII | B21: PEKERJAAN BANGUNAN IPAL BIOTECH | C21: ='Sub Resume'!C122 -> 35886105
B22: JUMLAH | C22: =C6+C7+C8+C9+C10+C11+C12+C13+C14+C15+C16+C17+C18+C19+C20+C21 -> 3723269226
B23: PPN 11% | C23: =ROUND(C22*11%,0) -> 409559615
B24: JUMLAH TOTAL | C24: =C22+C23 -> 4132828841
B25: DIBULATKAN | C25: =ROUNDDOWN(C24,-3) -> 4132828000

Sheet Sub Resume
A1: RENCANA ANGGARAN BIAYA – SUB RESUME
A2: Lokasi: Pesisir · Paket: KNMP Situbondo · CV. Tosan
A3: Kontrak: B.17114/DJPT.6/PI.420/PPK/VI/2026 · RAB revisi aktif #1
A5: Kode | B5: Uraian | C5: Jumlah Harga (Rp)
A6: I | B6: PEKERJAAN PERSIAPAN
A7: 1 | B7: Buat Bedeng Pekerja Dan Gudang | C7: ='Detail RAB'!F7 -> 63000000
A8: 2 | B8: Pekerjaan Sewa Rumah untuk Direksi Keetz | C8: ='Detail RAB'!F8 -> 14100000
A9: 3 | B9: Papan Nama Proyek | C9: ='Detail RAB'!F9 -> 1985634
A10: 4 | B10: Listrik Kerja | C10: ='Detail RAB'!F10 -> 4980000
A11: 5 | B11: Pekerjaan Pagar Sementara | C11: ='Detail RAB'!F11 -> 55500000
A12: 6 | B12: Pekerjaan Pengadaan SMK3K | C12: ='Detail RAB'!F12 -> 88974411
A13: 7 | B13: Pekerjaan Pembersihan Lokasi dari Pohon dan Rumput (Land Clearing) | C13: ='Detail RAB'!F44 -> 9900200
A14: 8 | B14: Pekerjaan Stake Out Posisi Trase Saluran/Infrastruktur | C14: ='Detail RAB'!F45 -> 5034000
A15: 9 | B15: Pekerjaan Sondir termasuk Pelaporan termasuk mobilisasi Alat dan Personil | C15: ='Detail RAB'!F46 -> 33300000
A16: 10 | B16: Mobilisasi dan Demobilisasi | C16: ='Detail RAB'!F47 -> 55378468
A17: 11 | B17: Pekerjaan Sambungan Daya Baru Gudang Beku | C17: ='Detail RAB'!F55 -> 48144573
A18: 12 | B18: Pekerjaan Sambungan Daya Baru Pabrik Es | C18: ='Detail RAB'!F58 -> 25060267
A19: 13 | B19: Pekerjaan Sambungan Daya Baru Kawasan | C19: ='Detail RAB'!F61 -> 16449468
A20: 14 | B20: Pekerjaan Panel Distribusi Kawasan, LVMDP/PDTR 25KVA, termasuk pengiriman dan instalasi | C20: ='Detail RAB'!F64 -> 17890000
A21: 15 | B21: Pekerjaan Pengadaan Tempat Sampah Portable 1100 L ex. Krisbow + Pengiriman | C21: ='Detail RAB'!F65 -> 21000000
B22: JUMLAH I – PEKERJAAN PERSIAPAN | C22: =C7+C8+C9+C10+C11+C12+C13+C14+C15+C16+C17+C18+C19+C20+C21 -> 460697021
A24: II | B24: PEKERJAAN REVETMENT
A25: 1 | B25: Pekerjaan Pondasi | C25: ='Detail RAB'!F67 -> 114379316
A26: 2 | B26: Pekerjaan Trap Tangga Beton lebar 60 cm | C26: ='Detail RAB'!F71 -> 45800313
A27: 3 | B27: Pekerjaan Trap Tangga Beton lebar 30 cm | C27: ='Detail RAB'!F76 -> 3358058
A28: 4 | B28: Pekerjaan Dinding Beton Penutup Trap t = 20 cm | C28: ='Detail RAB'!F83 -> 10255955
A29: 5 | B29: Pekerjaan Pondasi Tapak (untuk ddg Landing Stair) | C29: ='Detail RAB'!F88 -> 9664197
A30: 6 | B30: Pekerjaan Tapak Beton Menerus 30 x 200 cm | C30: ='Detail RAB'!F93 -> 46003576
A31: 7 | B31: Pekerjaan Dinding Beton t = 20 cm | C31: ='Detail RAB'!F101 -> 78474481
B32: JUMLAH II – PEKERJAAN REVETMENT | C32: =C25+C26+C27+C28+C29+C30+C31 -> 307935896
A34: V | B34: PEKERJAAN BANGUNAN SHELTER PENDARATAN IKAN
A35: V.1 | B35: Pekerjaan Struktural | C35: ='Detail RAB'!F108 -> 87667627
A36: V.2 | B36: Pekerjaan Arsitektural | C36: ='Detail RAB'!F171 -> 127415915
A37: V.3 | B37: Pekerjaan Elektrikal | C37: ='Detail RAB'!F198 -> 14352765
B38: JUMLAH V – PEKERJAAN BANGUNAN SHELTER PENDARATAN IKAN | C38: =C35+C36+C37 -> 229436307
A40: VI | B40: PEKERJAAN PONDASI GUDANG BEKU PORTABLE
A41: VI.1 | B41: Pekerjaan Struktural Pondasi | C41: ='Detail RAB'!F206 -> 221281232
B42: JUMLAH VI – PEKERJAAN PONDASI GUDANG BEKU PORTABLE | C42: =C41 -> 221281232
A44: VII | B44: PEKERJAAN PONDASI PABRIK ES PORTABLE
A45: VII.1 | B45: Pekerjaan Struktural Pondasi | C45: ='Detail RAB'!F256 -> 115041813
...

Sheet Detail RAB
A1: RENCANA ANGGARAN BIAYA – DETAIL
A2: Lokasi: Pesisir · Paket: KNMP Situbondo · CV. Tosan
A3: Kontrak: B.17114/DJPT.6/PI.420/PPK/VI/2026 · RAB revisi aktif #1
A5: Kode | B5: Uraian Pekerjaan | C5: Volume | D5: Sat | E5: Harga Satuan (Rp) | F5: Jumlah (Rp)
A6: I | B6: PEKERJAAN PERSIAPAN | F6: =F7+F8+F9+F10+F11+F12+F44+F45+F46+F47+F55+F58+F61+F64+F65 -> 460697021
A7: 1 | B7: Buat Bedeng Pekerja Dan Gudang | C7: 50 | D7: m² | E7: 1260000 | F7: 63000000
A8: 2 | B8: Pekerjaan Sewa Rumah untuk Direksi Keetz | C8: 6 | D8: bln | E8: 2350000 | F8: 14100000
A9: 3 | B9: Papan Nama Proyek | C9: 1 | D9: bh | E9: 1985634.6 | F9: 1985634
A10: 4 | B10: Listrik Kerja | C10: 6 | D10: bln | E10: 830000 | F10: 4980000
A11: 5 | B11: Pekerjaan Pagar Sementara | C11: 150 | D11: m¹ | E11: 370000 | F11: 55500000
A12: 6 | B12: Pekerjaan Pengadaan SMK3K | F12: =F13+F16+F19+F21+F27+F29+F31+F33+F38 -> 88974411
A13: 6.1 | B13: Penyiapan RK3K, terdiri atas : | F13: =F14+F15 -> 2471221
A14: 6.1.a | B14: Pembuatan Manual, Prosedur, Instruksi Kerja, Ijin Kerja dan Formulir | C14: 2 | D14: set | E14: 972000 | F14: 1944000
A15: 6.1.b | B15: Pembuatan Kartu Identitas Pekerja (KIP) | C15: 80 | D15: org | E15: 6590.26 | F15: 527221
A16: 6.2 | B16: Sosialisasi dan Promosi K3, terdiri atas : | F16: =F17+F18 -> 1251204
A17: 6.2.a | B17: Induksi K3 (Safety Induction) ; khusus untuk pekerja baru | C17: 80 | D17: org | E17: 7746.23 | F17: 619698
A18: 6.2.b | B18: Pengarahan K3 (Safety Briefing) : | C18: 80 | D18: org | E18: 7893.82 | F18: 631506
A19: 6.3 | B19: Alat Pelindung Kerja, terdiri atas : | F19: =F20 -> 118231
A20: 6.3.a | B20: Pembatas Area (Restricted Area) | C20: 1 | D20: ls | E20: 118230.96 | F20: 118231
A21: 6.4 | B21: Alat Pelindung Diri, terdiri atas : | F21: =F22+F23+F24+F25+F26 -> 19388303
A22: 6.4.a | B22: Topi Pelindung (Safety Helmet) | C22: 80 | D22: bh | E22: 75274.15 | F22: 6021932
A23: 6.4.b | B23: Pelindung Pernapasan dan Mulut (Masker) | C23: 80 | D23: bh | E23: 5268.15 | F23: 421452
A24: 6.4.c | B24: Sarung Tangan (Safety Gloves) | C24: 80 | D24: psg | E24: 5138.25 | F24: 411060
A25: 6.4.d | B25: Sepatu Keselamatan (Rubber Safety Shoes and Toe Cap) | C25: 80 | D25: psg | E25: 130000 | F25: 10400000
A26: 6.4.e | B26: Rompi Keselamatan ( Safety vest) | C26: 80 | D26: bh | E26: 26673.24 | F26: 2133859
A27: 6.5 | B27: Asuransi dan Perijinan, terdiri atas : | F27: =F28 -> 18000000
A28: 6.5.a | B28: BPJS Ketenagakerjaan dan Kesehatan Kerja ; (BERDASARKAN KEPMENAKER NOMOR 44 TAHUN 2015 tentang | C28: 1 | D28: ls | E28: 18000000 | F28: 18000000
A29: 6.6 | B29: Personil K3, terdiri atas : | F29: =F30 -> 36000000
A30: 6.6.a | B30: Petugas K3 | C30: 6 | D30: bln | E30: 6000000 | F30: 36000000
A31: 6.7 | B31: Fasilitas Sarana Kesehatan, terdiri atas : | F31: =F32 -> 5000000
A32: 6.7.1 | B32: Peralatan P3K (Kotak P3K, Tandu, Tabung Oksigen, Obat Luka, Perban, dll) | C32: 1 | D32: ls | E32: 5000000 | F32: 5000000
A33: 6.8 | B33: Rambu-rambu ukuran min. 90x90, terdiri atas : | F33: =F34+F35+F36+F37 -> 1242563
A34: 6.8.a | B34: Rambu Petunjuk | C34: 5 | D34: bh | E34: 70798.25 | F34: 353991
A35: 6.8.b | B35: Rambu Larangan | C35: 2 | D35: bh | E35: 74587.22 | F35: 149174
A36: 6.8.c | B36: Rambu Peringatan | C36: 5 | D36: bh | E36: 74901.01 | F36: 374505
A37: 6.8.d | B37: Rambu Kewajiban | C37: 5 | D37: bh | E37: 72978.5 | F37: 364893
A38: 6.9 | B38: Lain-lain Terkait Pengendalian Resiko K3, terdiri atas : | F38: =F39+F40+F41+F42+F43 -> 5502889
A39: 6.9.a | B39: Alat Pemadam Api Ringan (APAR) ; 3 kg | C39: 2 | D39: bh | E39: 681797.36 | F39: 1363595
A40: 6.9.b | B40: Bendera K3 | C40: 2 | D40: bh | E40: 41466.95 | F40: 82934
A41: 6.9.c | B41: Jalur Evakuasi (Escape Route) | C41: 3 | D41: ls | E41: 511960.33 | F41: 1535881
...
